Workbook
Name _Toc301930468: TestDesign!$B$219
Name _Toc301930478: TestDesign!$B$379
Name ACTION: #REF!
Name LOCAL_DATE_SEPARATOR: #REF!
Name LOCAL_DAY_FORMAT: #REF!
Name LOCAL_HOUR_FORMAT: #REF!
Name LOCAL_MINUTE_FORMAT: #REF!
Name LOCAL_MONTH_FORMAT: #REF!
Name LOCAL_SECOND_FORMAT: #REF!
Name LOCAL_TIME_SEPARATOR: #REF!
Name LOCAL_YEAR_FORMAT: #REF!

Sheet Cover
B2: TEST CASE
B4: Project Name | C4: nopCommerce Demo | F4: Creator | G4: Lê Hữu Phước
B5: Project Code | C5: NOP | F5: Reviewer/Approver | G5: ThS. Trần Thị Thanh Nga
B6: Document Code | C6: =C5&"_TestCase_V0.1" -> NOP_TestCase_V0.1 | F6: Issue Date | G6: 46317
F7: Version | G7: 0.1
B8: AUT (URL) | C8: https://demo.nopcommerce.com/register
B10: Record of change
B11: Effective Date | C11: Version | D11: Change Item | E11: *A,D,M | F11: Change description | G11: Reference
B12: 46318 | C12: 0.1 | E12: A | F12: Tạo Test Design và test case cho 4 module của nopCommerce Demo: Đăng ký, đăng nhập, đăng xuất (Register-Login-Logout, 83 test case); Khuyến mãi - Discounts (Promotions, 48 test case); Affiliates (Promotions, 42 test case); Newsletter subscribers (Promotions, 61 test case) | G12: nopCommerce documentation (docs.nopcommerce.com); admin-demo.nopcommerce.com/Admin/Discount/List; admin-demo.nopcommerce.com/Admin/Affiliate/List; admin-demo.nopcommerce.com/Admin/NewsLetterSubscription/List

Sheet Test case List
D1: TEST CASE LIST
B3: Project Name | D3: =Cover!C4 -> nopCommerce Demo
B4: Project Code | D4: =Cover!C5 -> NOP
B5: Test Environment Setup Description | D5: 1. Storefront: https://demo.nopcommerce.com/ (khách hàng) 2. Admin: https://admin-demo.nopcommerce.com/admin/ (tài khoản admin được điền sẵn trên trang đăng nhập), dùng để kiểm tra khách hàng mới, Newsletter subscribers, danh sách Discounts và danh sách Affiliates 3. Trình duyệt: Chrome, Firefox, Edge bản mới nhất; thử thêm chế độ mobile 4. Lưu ý: demo dùng chung và dữ liệu được reset định kỳ; mỗi lần đăng ký dùng email mới (ví dụ phuoc.test01@example.com) và ghi nhận thông báo thực tế khi khác mô tả
B8: No | C8: Function Name | D8: Sheet Name | E8: Description | F8: Pre-Condition
B9: 1 | C9: Đăng ký, đăng nhập, đăng xuất | D9: Register-Login-Logout | E9: Đăng ký (form Gender, First name, Last name, Email, Company name, Newsletter, Password, Confirm password: giao diện, thành công, bỏ trống, email, mật khẩu, họ tên/Company name, newsletter, bảo mật, điều hướng); Đăng nhập (giao diện, thành công, không thành công, bảo mật, quên mật khẩu); Đăng xuất | F9: Chưa đăng nhập; chuẩn bị email chưa đăng ký và tài khoản khách hàng hợp lệ; có tài khoản admin demo cho các case kiểm tra trên trang admin
B10: 2 | C10: Khuyến mãi (Promotions) | D10: Promotions | E10: Discounts (Promotions > Discounts) - danh sách: hiển thị trang, khối Search (Start date, End date, Discount type, Vendor, Coupon code, Discount name, Is active), bảng kết quả, phân trang, điều hướng ([Add new], [Edit], menu), bảo mật | F10: Đã đăng nhập trang admin demo (https://admin-demo.nopcommerce.com/admin/); dữ liệu mặc định có 2 discount ("'20% order total' discount", "Sample discount with coupon code"); chỉ xem và tìm kiếm, không lưu thay đổi dữ liệu
B11: 3 | C11: Affiliates (Promotions) | D11: Admin - Promotions - Affiliates | E11: Affiliates (Promotions > Affiliates) - danh sách: hiển thị trang, khối Search (First name, Last name, Friendly URL name, Load only with orders), bảng kết quả (First name, Last name, Active, Edit), phân trang, điều hướng ([Add new], [Edit], menu), bảo mật | F11: Đã đăng nhập trang admin demo (https://admin-demo.nopcommerce.com/admin/); dữ liệu mặc định có 1 affiliate (John Smith); chỉ xem và tìm kiếm, không lưu thay đổi dữ liệu
B12: 4 | C12: Newsletter subscribers (Promotions) | D12: Admin - Promotions - Newsletter | E12: Newsletter subscribers (Promotions > Newsletter subscribers) - danh sách: hiển thị trang, chuẩn bị dữ liệu từ storefront, khối Search (Email, Start date, End date, Active, Customer role, Subscription type), bảng kết quả, phân trang, [Export to CSV], [Import from CSV], điều hướng ([Add new], [Edit], menu), bảo mật | F12: Đã đăng nhập trang admin demo; danh sách mặc định chưa có subscriber (No records); cần tạo 2 subscriber từ storefront (đăng ký tài khoản có tích Newsletter và ô Newsletter ở footer) bằng email chưa dùng; không lưu thay đổi trực tiếp trên trang admin

Sheet TestDesign
A1: Requirement Level 1 | B1: Requirement Level 2 | C1: Requirement Level 3 | D1: Test Criteria | E1: Test Type | F1: Note
A2: 1. Đăng ký, đăng nhập, đăng xuất | B2: 1.1 Đăng ký | C2: Hiển thị | D2: Kiểm tra mở trang đăng ký từ liên kết [Register] trên header | E2: Function
D3: Kiểm tra truy cập trực tiếp bằng URL /register và header khi chưa đăng nhập | E3: GUI
D4: Kiểm tra các nhóm và trường trên form đăng ký | E4: GUI
D5: Kiểm tra dấu * ở các trường bắt buộc và giá trị mặc định của form | E5: GUI
D6: Kiểm tra Gender chỉ cho chọn một giá trị | E6: Function
D7: Kiểm tra ô Password và Confirm password ẩn ký tự | E7: Function
D8: Kiểm tra thao tác bằng bàn phím (Tab, Enter) | E8: Function
D9: Kiểm tra layout form trên desktop và mobile | E9: GUI
C10: Thành công | D10: Kiểm tra đăng ký thành công khi nhập đủ thông tin hợp lệ (Male, có Company name, tích Newsletter) | E10: Function | F10: Ghi lại email dùng ở case này cho các case phụ thuộc; nếu demo đã reset dữ liệu thì chạy lại case này
D11: Kiểm tra đăng ký thành công khi chỉ nhập các trường bắt buộc | E11: Function
D12: Kiểm tra đăng ký thành công khi chọn Female và bỏ tích Newsletter | E12: Function
D13: Kiểm tra nút [Continue] và trạng thái đăng nhập sau khi đăng ký | E13: Function
D14: Kiểm tra thông tin tài khoản được lưu đúng | E14: Function
D15: Kiểm tra đăng nhập lại bằng tài khoản vừa đăng ký | E15: Function
D16: Kiểm tra khách hàng mới hiển thị trong trang admin | E16: Function
D17: Kiểm tra đăng ký với tên tiếng Việt có dấu | E17: Function
D18: Kiểm tra đăng ký với tên có dấu nháy và gạch nối | E18: Function
D19: Kiểm tra đăng ký với Email có dấu "+" và dấu chấm | E19: Function
D20: Kiểm tra đăng ký với Email viết hoa rồi đăng nhập bằng chữ thường | E20: Function
D21: Kiểm tra đăng ký với mật khẩu chứa ký tự đặc biệt | E21: Function
D22: Kiểm tra giỏ hàng vãng lai được giữ lại sau khi đăng ký | E22: Function
D23: Kiểm tra wishlist vãng lai được giữ lại sau khi đăng ký | E23: Function
C24: Bỏ trống trường | D24: Kiểm tra để trống First name | E24: Function
D25: Kiểm tra để trống Last name | E25: Function
D26: Kiểm tra để trống Email | E26: Function
D27: Kiểm tra để trống Password | E27: Function
D28: Kiểm tra để trống Confirm password | E28: Function
D29: Kiểm tra để trống toàn bộ form | E29: Function
D30: Kiểm tra First name và Last name chỉ gồm khoảng trắng | E30: Function
D31: Kiểm tra Password và Confirm password chỉ gồm khoảng trắng | E31: Function | F31: Xác nhận nội dung thông báo thực tế khi chạy
D32: Kiểm tra thông báo lỗi biến mất sau khi nhập đúng | E32: Function
C33: Email | D33: Kiểm tra Email sai định dạng: thiếu @ và tên miền | E33: Function
D34: Kiểm tra Email sai định dạng: thiếu phần mở rộng tên miền (.com) | E34: Function | F34: Nếu demo chấp nhận email không có phần mở rộng tên miền thì ghi nhận Fail
D35: Kiểm tra Email sai định dạng: thiếu phần tên trước @ | E35: Function
D36: Kiểm tra Email sai định dạng: có 2 dấu @ | E36: Function
D37: Kiểm tra Email sai định dạng: có khoảng trắng ở giữa | E37: Function
D38: Kiểm tra Email chứa mã script | E38: Function
D39: Kiểm tra Email đã tồn tại | E39: Function
D40: Kiểm tra Email đã tồn tại nhưng khác chữ hoa / thường | E40: Function
...

Sheet User - Register-Login-Logout
A2: Module Code | B2: User - Register-Login-Logout | J2: Passed
A3: Test requirement | B3: Đăng ký, đăng nhập, đăng xuất | J3: Failed
A4: Tester | B4: Lê Hữu Phước | J4: Blocked
A5: Passed | B5: Failed | C5: Untested | D5: Blocked | E5: Skipped | F5: Number of Test cases | J5: Untested
A6: =COUNTIF(F9:F996,"Passed") -> 58 | B6: =COUNTIF(F9:F996,"Failed") -> 25 | C6: =F6-E6-D6-B6-A6 -> 0 | D6: =COUNTIF(F$9:F$996,"Blocked") -> 0 | E6: =COUNTIF(F$9:F$996,"Skipped") -> 0 | F6: =COUNTA(A9:A996) -> 83 | J6: Skipped
A8: ID | B8: Test Case Description | C8: Test Case Procedure | D8: Expected Output | E8: Inter-test case Dependence | F8: Result | G8: Test date | H8: Note
A9: AUTH_REG_View_01 | B9: Kiểm tra mở trang đăng ký từ liên kết [Register] trên header | C9: Pre-condition: + Chưa đăng nhập Step: 1. Mở https://demo.nopcommerce.com/ 2. Click [Register] ở góc trên bên phải | D9: 1. Hiển thị trang chủ, header có [Register] và [Log in] 2. Hiển thị trang Register (URL /register), tiêu đề trang là "Register" | F9: Passed
A10: AUTH_REG_View_02 | B10: Kiểm tra truy cập trực tiếp bằng URL /register và header khi chưa đăng nhập | C10: Pre-condition: + Chưa đăng nhập Step: 1. Nhập URL https://demo.nopcommerce.com/register vào thanh địa chỉ 2. Quan sát header | D10: 1. Hiển thị trang Register, menu danh mục hiển thị bình thường 2. Header hiển thị [Register], [Log in], Wishlist (0), Shopping cart (0), ô Search store, ô chọn tiền tệ; chưa có [My account] / [Log out] | F10: Passed
A11: AUTH_REG_View_03 | B11: Kiểm tra các nhóm và trường trên form đăng ký | C11: 1. Mở trang Register 2. Quan sát form | D11: 1. Hiển thị trang Register 2. Có 4 nhóm: Your Personal Details (Gender Male/Female, First name, Last name, Email), Company Details (Company name), Subscribe to newsletter (Newsletter), Your Password (Password, Confirm password); có nút [REGISTER] | F11: Failed
A12: AUTH_REG_View_04 | B12: Kiểm tra dấu * ở các trường bắt buộc và giá trị mặc định của form | C12: 1. Mở trang Register mới (chưa nhập gì) 2. Quan sát dấu * bên cạnh các trường 3. Quan sát giá trị mặc định của các trường | D12: 1. Hiển thị trang Register 2. Dấu * chỉ có ở First name, Last name, Email, Password, Confirm password; Gender, Company name, Newsletter không có dấu * 3. Gender chưa chọn; các ô nhập đều trống; Newsletter được tích sẵn | F12: Failed
A13: AUTH_REG_View_05 | B13: Kiểm tra Gender chỉ cho chọn một giá trị | C13: 1. Click chọn Male 2. Click chọn Female | D13: 1. Male được chọn 2. Female được chọn và Male tự bỏ chọn (radio button) | F13: Passed
A14: AUTH_REG_View_06 | B14: Kiểm tra ô Password và Confirm password ẩn ký tự | C14: 1. Nhập "Test@123456" vào ô Password 2. Nhập "Test@123456" vào ô Confirm password | D14: 1. Ký tự hiển thị dạng dấu chấm, không lộ mật khẩu 2. Ký tự hiển thị dạng dấu chấm, không lộ mật khẩu | F14: Passed
A15: AUTH_REG_View_07 | B15: Kiểm tra thao tác bằng bàn phím (Tab, Enter) | C15: Pre-condition: + Chưa đăng nhập, đang ở trang Register + Dùng email chưa đăng ký (mỗi lần test dùng email mới, ví dụ phuoc.test01@example.com) + Dữ liệu hợp lệ: First name "Phuoc", Last name "Le", Password và Confirm password "Test@123456" Step: 1. Click vào ô First name, nhấn Tab liên tục 2. Nhập dữ liệu hợp lệ vào các ô, đứng ở ô Confirm password rồi nhấn Enter | D15: 1. Con trỏ di chuyển theo thứ tự: Last name, Email, Company name, Newsletter, Password, Confirm password, [REGISTER] 2. Form được gửi, đăng ký thành công | F15: Passed
A16: AUTH_REG_View_08 | B16: Kiểm tra layout form trên desktop và mobile | C16: 1. Xem form trên desktop 2. Thu nhỏ trình duyệt về kích thước mobile | D16: 1. Form căn giữa, nhãn và ô nhập thẳng hàng 2. Form co giãn đúng, không tràn khung, nút [REGISTER] vẫn thao tác được | F16: Passed
A17: AUTH_REG_Success_01 | B17: Kiểm tra đăng ký thành công khi nhập đủ thông tin hợp lệ (Male, có Company name, tích Newsletter) | C17: Pre-condition: + Chưa đăng nhập, đang ở trang Register + Dùng email chưa đăng ký (mỗi lần test dùng email mới, ví dụ phuoc.test01@example.com) Step: 1. Chọn Male; nhập First name "Phuoc", Last name "Le", Email chưa dùng, Company name "ABC Co., Ltd" 2. Nhập Password và Confirm password "Test@123456", giữ nguyên Newsletter được tích sẵn 3. Click [REGISTER] | D17: 1. Dữ liệu được nhập, không báo lỗi 2. Mật khẩu hiển thị dạng dấu chấm; Newsletter vẫn được tích 3. Hiển thị "Your registration completed" và nút [Continue] | F17: Passed | H17: Ghi lại email dùng ở case này cho các case phụ thuộc; nếu demo đã reset dữ liệu thì chạy lại case này
A18: AUTH_REG_Success_02 | B18: Kiểm tra đăng ký thành công khi chỉ nhập các trường bắt buộc | C18: Pre-condition: + Chưa đăng nhập, đang ở trang Register + Dùng email chưa đăng ký (mỗi lần test dùng email mới, ví dụ phuoc.test01@example.com) + Dữ liệu hợp lệ: First name "Phuoc", Last name "Le", Password và Confirm password "Test@123456" Step: 1. Bỏ trống Gender và Company name; nhập First name, Last name, Email, Password, Confirm password hợp lệ 2. Click [REGISTER] | D18: 1. Dữ liệu được nhập, không báo lỗi 2. Đăng ký thành công, không báo lỗi ở Gender và Company name | F18: Passed
A19: AUTH_REG_Success_03 | B19: Kiểm tra đăng ký thành công khi chọn Female và bỏ tích Newsletter | C19: Pre-condition: + Chưa đăng nhập, đang ở trang Register + Dùng email chưa đăng ký (mỗi lần test dùng email mới, ví dụ phuoc.test01@example.com) + Dữ liệu hợp lệ: First name "Phuoc", Last name "Le", Password và Confirm password "Test@123456" Step: 1. Chọn Female, bỏ tích Newsletter, nhập các trường bắt buộc hợp lệ 2. Click [REGISTER] 3. Click [My account] > [Customer info] | D19: 1. Female được chọn, Newsletter không còn được tích 2. Hiển thị "Your registration completed" 3. Gender là Female, Newsletter không được tích | F19: Failed
A20: AUTH_REG_Success_04 | B20: Kiểm tra nút [Continue] và trạng thái đăng nhập sau khi đăng ký | C20: Pre-condition: + Vừa hoàn thành AUTH_REG_Success_01, đang ở màn hình "Your registration completed" Step: 1. Click [Continue] 2. Quan sát header | D20: 1. Chuyển về trang chủ 2. Header hiển thị [My account], [Log out], Wishlist (0), Shopping cart (0); không còn [Register] / [Log in] | E20: AUTH_REG_Success_01 | F20: Passed
A21: AUTH_REG_Success_05 | B21: Kiểm tra thông tin tài khoản được lưu đúng | C21: Pre-condition: + Đã hoàn thành AUTH_REG_Success_04 (đang đăng nhập bằng tài khoản của AUTH_REG_Success_01) Step: 1. Click [My account] 2. Quan sát thông tin trong [Customer info] | D21: 1. Hiển thị trang Customer info 2. Gender, First name, Last name, Email, Company name đúng với dữ liệu đã nhập ở AUTH_REG_Success_01; Newsletter được tích | E21: AUTH_REG_Success_04 | F21: Failed
A22: AUTH_REG_Success_06 | B22: Kiểm tra đăng nhập lại bằng tài khoản vừa đăng ký | C22: Pre-condition: + Đang đăng nhập bằng tài khoản của AUTH_REG_Success_01 Step: 1. Click [Log out] 2. Click [Log in], đăng nhập bằng email và mật khẩu của AUTH_REG_Success_01 | D22: 1. Đăng xuất thành công, header hiển thị lại [Register] / [Log in] 2. Đăng nhập thành công vào đúng tài khoản | E22: AUTH_REG_Success_01 | F22: Passed
A23: AUTH_REG_Success_07 | B23: Kiểm tra khách hàng mới hiển thị trong trang admin | C23: Pre-condition: + Chưa đăng nhập + Có tài khoản admin demo (https://admin-demo.nopcommerce.com/admin/) + Đã hoàn thành AUTH_REG_Success_01 (dùng email của tài khoản đó) Step: 1. Đăng nhập trang admin 2. Mở [Customers] > [Customers], tìm email của AUTH_REG_Success_01 | D23: 1. Đăng nhập admin thành công 2. Khách hàng xuất hiện trong danh sách với đúng họ tên, email và nhóm [Registered] | E23: AUTH_REG_Success_01 | F23: Passed
A24: AUTH_REG_Success_08 | B24: Kiểm tra đăng ký với tên tiếng Việt có dấu | C24: Pre-condition: + Chưa đăng nhập, đang ở trang Register + Dùng email chưa đăng ký (mỗi lần test dùng email mới, ví dụ phuoc.test01@example.com) + Dữ liệu hợp lệ: First name "Phuoc", Last name "Le", Password và Confirm password "Test@123456" Step: 1. Nhập First name "Phước", Last name "Lê Hữu", các trường còn lại hợp lệ 2. Click [REGISTER] 3. Click [My account] > [Customer info] | D24: 1. Họ tên hiển thị đúng dấu trong ô nhập 2. Đăng ký thành công 3. Họ tên hiển thị đúng dấu, không lỗi font | F24: Passed
A25: AUTH_REG_Success_09 | B25: Kiểm tra đăng ký với tên có dấu nháy và gạch nối | C25: Pre-condition: + Chưa đăng nhập, đang ở trang Register + Dùng email chưa đăng ký (mỗi lần test dùng email mới, ví dụ phuoc.test01@example.com) + Dữ liệu hợp lệ: First name "Phuoc", Last name "Le", Password và Confirm password "Test@123456" Step: 1. Nhập First name "Anne-Marie", Last name "O'Neil", các trường còn lại hợp lệ 2. Click [REGISTER] 3. Click [My account] > [Customer info] | D25: 1. Họ tên hiển thị đúng như đã nhập 2. Đăng ký thành công 3. Họ tên lưu và hiển thị đúng "Anne-Marie" và "O'Neil" | F25: Passed
A26: AUTH_REG_Success_10 | B26: Kiểm tra đăng ký với Email có dấu "+" và dấu chấm | C26: Pre-condition: + Chưa đăng nhập, đang ở trang Register + Dùng email chưa đăng ký (mỗi lần test dùng email mới, ví dụ phuoc.test01@example.com) + Dữ liệu hợp lệ: First name "Phuoc", Last name "Le", Password và Confirm password "Test@123456" Step: 1. Nhập Email "phuoc.le+test03@example.com", các trường còn lại hợp lệ 2. Click [REGISTER] 3. Click [My account] > [Customer info] | D26: 1. Email hiển thị đúng như đã nhập 2. Đăng ký thành công 3. Email lưu và hiển thị đúng "phuoc.le+test03@example.com" | F26: Passed
A27: AUTH_REG_Success_11 | B27: Kiểm tra đăng ký với Email viết hoa rồi đăng nhập bằng chữ thường | C27: Pre-condition: + Chưa đăng nhập, đang ở trang Register + Dùng email chưa đăng ký (mỗi lần test dùng email mới, ví dụ phuoc.test01@example.com) + Dữ liệu hợp lệ: First name "Phuoc", Last name "Le", Password và Confirm password "Test@123456" Step: 1. Nhập Email "Phuoc.Test02@Example.COM", các trường còn lại hợp lệ 2. Click [REGISTER] 3. Click [Log out] 4. Click [Log in], đăng nhập bằng email "phuoc.test02@example.com" và mật khẩu đã đăng ký | D27: 1. Email hiển thị đúng như đã nhập 2. Đăng ký thành công 3. Đăng xuất thành công 4. Đăng nhập thành công (email không phân biệt hoa thường) | F27: Passed
A28: AUTH_REG_Success_12 | B28: Kiểm tra đăng ký với mật khẩu chứa ký tự đặc biệt | C28: Pre-condition: + Chưa đăng nhập, đang ở trang Register + Dùng email chưa đăng ký (mỗi lần test dùng email mới, ví dụ phuoc.test01@example.com) + Dữ liệu hợp lệ: First name "Phuoc", Last name "Le", Password và Confirm password "Test@123456" Step: 1. Nhập Password và Confirm password "P@ss!#$%^&*()_+w0rd", các trường còn lại hợp lệ 2. Click [REGISTER] 3. Click [Log out], rồi đăng nhập lại bằng mật khẩu đó | D28: 1. Mật khẩu hiển thị dạng dấu chấm 2. Đăng ký thành công 3. Đăng nhập thành công | F28: Passed
A29: AUTH_REG_Success_13 | B29: Kiểm tra giỏ hàng vãng lai được giữ lại sau khi đăng ký | C29: Pre-condition: + Chưa đăng nhập + Dùng email chưa đăng ký (mỗi lần test dùng email mới, ví dụ phuoc.test01@example.com) + Dữ liệu hợp lệ: First name "Phuoc", Last name "Le", Password và Confirm password "Test@123456" Step: 1. Mở trang chi tiết một sản phẩm không yêu cầu chọn thuộc tính, click [Add to cart] 2. Mở trang Register, đăng ký tài khoản mới với dữ liệu hợp lệ 3. Click [Shopping cart] | D29: 1. Header hiển thị Shopping cart (1) 2. Đăng ký thành công 3. Giỏ hàng vẫn còn sản phẩm đã thêm | F29: Passed
A30: AUTH_REG_Success_14 | B30: Kiểm tra wishlist vãng lai được giữ lại sau khi đăng ký | C30: Pre-condition: + Chưa đăng nhập + Dùng email chưa đăng ký (mỗi lần test dùng email mới, ví dụ phuoc.test01@example.com) + Dữ liệu hợp lệ: First name "Phuoc", Last name "Le", Password và Confirm password "Test@123456" Step: 1. Mở trang chi tiết một sản phẩm không yêu cầu chọn thuộc tính, click [Add to wishlist] 2. Mở trang Register, đăng ký tài khoản mới với dữ liệu hợp lệ 3. Click [Wishlist] | D30: 1. Header hiển thị Wishlist (1) 2. Đăng ký thành công 3. Wishlist vẫn còn sản phẩm đã thêm | F30: Passed
A31: AUTH_REG_Empty_01 | B31: Kiểm tra để trống First name | C31: Pre-condition: + Chưa đăng nhập, đang ở trang Register + Dùng email chưa đăng ký (mỗi lần test dùng email mới, ví dụ phuoc.test01@example.com) + Dữ liệu hợp lệ: First name "Phuoc", Last name "Le", Password và Confirm password "Test@123456" Step: 1. Để trống First name, nhập các trường còn lại hợp lệ 2. Click [REGISTER] | D31: 1. Các trường còn lại có dữ liệu, First name để trống 2. Hiển thị "First name is required."; không tạo tài khoản | F31: Passed
A32: AUTH_REG_Empty_02 | B32: Kiểm tra để trống Last name | C32: Pre-condition: + Chưa đăng nhập, đang ở trang Register + Dùng email chưa đăng ký (mỗi lần test dùng email mới, ví dụ phuoc.test01@example.com) + Dữ liệu hợp lệ: First name "Phuoc", Last name "Le", Password và Confirm password "Test@123456" Step: 1. Để trống Last name, nhập các trường còn lại hợp lệ 2. Click [REGISTER] | D32: 1. Các trường còn lại có dữ liệu, Last name để trống 2. Hiển thị "Last name is required."; không tạo tài khoản | F32: Passed
A33: AUTH_REG_Empty_03 | B33: Kiểm tra để trống Email | C33: Pre-condition: + Chưa đăng nhập, đang ở trang Register + Dùng email chưa đăng ký (mỗi lần test dùng email mới, ví dụ phuoc.test01@example.com) + Dữ liệu hợp lệ: First name "Phuoc", Last name "Le", Password và Confirm password "Test@123456" Step: 1. Để trống Email, nhập các trường còn lại hợp lệ 2. Click [REGISTER] | D33: 1. Các trường còn lại có dữ liệu, Email để trống 2. Hiển thị "Email is required."; không tạo tài khoản | F33: Passed
A34: AUTH_REG_Empty_04 | B34: Kiểm tra để trống Password | C34: Pre-condition: + Chưa đăng nhập, đang ở trang Register + Dùng email chưa đăng ký (mỗi lần test dùng email mới, ví dụ phuoc.test01@example.com) + Dữ liệu hợp lệ: First name "Phuoc", Last name "Le", Password và Confirm password "Test@123456" Step: 1. Để trống Password, nhập Confirm password "Test@123456", các trường còn lại hợp lệ 2. Click [REGISTER] | D34: 1. Ô Password trống, Confirm password có dữ liệu 2. Hiển thị "Password is required." ở ô Password; không tạo tài khoản | F34: Passed
A35: AUTH_REG_Empty_05 | B35: Kiểm tra để trống Confirm password | C35: Pre-condition: + Chưa đăng nhập, đang ở trang Register + Dùng email chưa đăng ký (mỗi lần test dùng email mới, ví dụ phuoc.test01@example.com) + Dữ liệu hợp lệ: First name "Phuoc", Last name "Le", Password và Confirm password "Test@123456" Step: 1. Nhập Password "Test@123456", để trống Confirm password, các trường còn lại hợp lệ 2. Click [REGISTER] | D35: 1. Ô Confirm password trống, Password có dữ liệu 2. Hiển thị "Password is required." ở ô Confirm password; không tạo tài khoản | F35: Passed
... A37: AUTH_REG_Empty_07 | B37: Kiểm tra First name và Last name chỉ gồm khoảng trắng | C37: Pre-condition: + Chưa đăng nhập, đang ở trang Register + Dùng email chưa đăng ký (mỗi lần test dùng email mới, ví dụ phuoc.test01@example.com) + Dữ liệu hợp lệ: First name "Phuoc", Last name "Le", Password và Confirm password "Test@123456" Step: 1. Nhập First name và Last name chỉ gồm 3 dấu cách, các trường còn lại hợp lệ 2. Click [REGISTER] | D37: 1. Hai ô họ tên chỉ chứa khoảng trắng 2. Hiển thị "First name is required." và "Last name is required."; không tạo tài khoản | F37: Passed
A38: AUTH_REG_Empty_08 | B38: Kiểm tra Password và Confirm password chỉ gồm khoảng trắng | C38: Pre-condition: + Chưa đăng nhập, đang ở trang Register + Dùng email chưa đăng ký (mỗi lần test dùng email mới, ví dụ phuoc.test01@example.com) + Dữ liệu hợp lệ: First name "Phuoc", Last name "Le", Password và Confirm password "Test@123456" Step: 1. Nhập Password và Confirm password gồm 6 dấu cách, các trường còn lại hợp lệ 2. Click [REGISTER] | D38: 1. Hai ô mật khẩu chứa 6 ký tự (dấu chấm) 2. Hiển thị thông báo lỗi ở ô Password; không tạo tài khoản | F38: Failed | H38: Xác nhận nội dung thông báo thực tế khi chạy
A39: AUTH_REG_Empty_09 | B39: Kiểm tra thông báo lỗi biến mất sau khi nhập đúng | C39: Pre-condition: + Chưa đăng nhập, đang ở trang Register + Dùng email chưa đăng ký (mỗi lần test dùng email mới, ví dụ phuoc.test01@example.com) + Dữ liệu hợp lệ: First name "Phuoc", Last name "Le", Password và Confirm password "Test@123456" Step: 1. Click [REGISTER] khi form trống 2. Nhập dữ liệu hợp lệ vào từng ô 3. Click [REGISTER] | D39: 1. Hiển thị lỗi ở 5 trường bắt buộc 2. Thông báo lỗi của từng ô biến mất khi ô đó được nhập đúng 3. Đăng ký thành công | F39: Failed
A40: AUTH_REG_Email_01 | B40: Kiểm tra Email sai định dạng: thiếu @ và tên miền | C40: Pre-condition: + Chưa đăng nhập, đang ở trang Register + Dùng email chưa đăng ký (mỗi lần test dùng email mới, ví dụ phuoc.test01@example.com) + Dữ liệu hợp lệ: First name "Phuoc", Last name "Le", Password và Confirm password "Test@123456" Step: 1. Nhập Email "abc", các trường còn lại hợp lệ 2. Click [REGISTER] | D40: 1. Các ô hiển thị đúng dữ liệu đã nhập 2. Hiển thị "Wrong email"; không tạo tài khoản | F40: Passed
A41: AUTH_REG_Email_02 | B41: Kiểm tra Email sai định dạng: thiếu phần mở rộng tên miền (.com) | C41: Pre-condition: + Chưa đăng nhập, đang ở trang Register + Dùng email chưa đăng ký (mỗi lần test dùng email mới, ví dụ phuoc.test01@example.com) + Dữ liệu hợp lệ: First name "Phuoc", Last name "Le", Password và Confirm password "Test@123456" Step: 1. Nhập Email "abc@example", các trường còn lại hợp lệ 2. Click [REGISTER] | D41: 1. Các ô hiển thị đúng dữ liệu đã nhập 2. Hiển thị "Wrong email"; không tạo tài khoản | F41: Passed | H41: Nếu demo chấp nhận email không có phần mở rộng tên miền thì ghi nhận Fail
A42: AUTH_REG_Email_03 | B42: Kiểm tra Email sai định dạng: thiếu phần tên trước @ | C42: Pre-condition: + Chưa đăng nhập, đang ở trang Register + Dùng email chưa đăng ký (mỗi lần test dùng email mới, ví dụ phuoc.test01@example.com) + Dữ liệu hợp lệ: First name "Phuoc", Last name "Le", Password và Confirm password "Test@123456" Step: 1. Nhập Email "@example.com", các trường còn lại hợp lệ 2. Click [REGISTER] | D42: 1. Các ô hiển thị đúng dữ liệu đã nhập 2. Hiển thị "Wrong email"; không tạo tài khoản | F42: Passed
A43: AUTH_REG_Email_04 | B43: Kiểm tra Email sai định dạng: có 2 dấu @ | C43: Pre-condition: + Chưa đăng nhập, đang ở trang Register + Dùng email chưa đăng ký (mỗi lần test dùng email mới, ví dụ phuoc.test01@example.com) + Dữ liệu hợp lệ: First name "Phuoc", Last name "Le", Password và Confirm password "Test@123456" Step: 1. Nhập Email "abc@@example.com", các trường còn lại hợp lệ 2. Click [REGISTER] | D43: 1. Các ô hiển thị đúng dữ liệu đã nhập 2. Hiển thị "Wrong email"; không tạo tài khoản | F43: Failed
...

Sheet Admin - Promotions - Discounts
A2: Module Code | B2: Admin - Promotions - Discounts | J2: Passed
A3: Test requirement | B3: Khuyến mãi (Promotions) - Discounts: danh sách discount trên trang admin | J3: Failed
A4: Tester | B4: Lê Hữu Phước | J4: Blocked
A5: Passed | B5: Failed | C5: Untested | D5: Blocked | E5: Skipped | F5: Number of Test cases | J5: Untested
A6: =COUNTIF(F9:F996,"Passed") -> 38 | B6: =COUNTIF(F9:F996,"Failed") -> 10 | C6: =F6-E6-D6-B6-A6 -> 0 | D6: =COUNTIF(F$9:F$996,"Blocked") -> 0 | E6: =COUNTIF(F$9:F$996,"Skipped") -> 0 | F6: =COUNTA(A9:A996) -> 48 | J6: Skipped
A8: ID | B8: Test Case Description | C8: Test Case Procedure | D8: Expected Output | E8: Inter-test case Dependence | F8: Result | G8: Test date | H8: Note
A9: PROMO_DIS_View_01 | B9: Kiểm tra mở trang Discounts từ menu Promotions | C9: Pre-condition: + Đã đăng nhập trang admin demo (https://admin-demo.nopcommerce.com/admin/) + Đang ở trang Dashboard Step: 1. Click menu [Promotions] ở thanh bên trái 2. Click [Discounts] | D9: 1. Menu Promotions mở rộng, gồm Discounts, Affiliates, Newsletter subscribers, Subscription types, Campaigns 2. Hiển thị trang Discounts (URL /Admin/Discount/List), mục Discounts được làm nổi bật trong menu, tiêu đề trang là "Discounts" | F9: Passed
A10: PROMO_DIS_View_02 | B10: Kiểm tra truy cập trực tiếp bằng URL /Admin/Discount/List | C10: Pre-condition: + Đã đăng nhập trang admin demo (https://admin-demo.nopcommerce.com/admin/) Step: 1. Nhập URL https://admin-demo.nopcommerce.com/Admin/Discount/List vào thanh địa chỉ 2. Quan sát header và menu bên trái | D10: 1. Hiển thị trang Discounts 2. Header có tên tài khoản và [Logout]; menu Promotions mở sẵn và mục Discounts được chọn | F10: Passed
A11: PROMO_DIS_View_03 | B11: Kiểm tra thông báo cảnh báo ở đầu trang | C11: Pre-condition: + Đã đăng nhập trang admin demo (https://admin-demo.nopcommerce.com/admin/) + Đang ở trang Promotions > Discounts, chưa nhập tiêu chí tìm kiếm Step: 1. Quan sát thanh thông báo màu vàng phía trên tiêu đề 2. Click dấu x ở góc phải thanh thông báo | D11: 1. Hiển thị nội dung "In order to use this functionality, you have to disable the following setting: Configuration > Catalog settings > Ignore discounts (sitewide)." 2. Thông báo được đóng, các phần còn lại của trang giữ nguyên | F11: Passed | H11: Thông báo chỉ hiển thị khi cấu hình Ignore discounts (sitewide) đang bật; ghi nhận hành vi thực tế sau khi tải lại trang
A12: PROMO_DIS_View_04 | B12: Kiểm tra các trường và nút trong khối Search | C12: Pre-condition: + Đã đăng nhập trang admin demo (https://admin-demo.nopcommerce.com/admin/) + Đang ở trang Promotions > Discounts, chưa nhập tiêu chí tìm kiếm Step: 1. Quan sát khối Search | D12: 1. Khối Search có các trường Start date, End date, Discount type, Vendor, Coupon code, Discount name, Is active và nút [Search]; mỗi nhãn có biểu tượng (?) | F12: Passed
A13: PROMO_DIS_View_05 | B13: Kiểm tra giá trị mặc định của khối Search | C13: Pre-condition: + Đã đăng nhập trang admin demo (https://admin-demo.nopcommerce.com/admin/) + Đang ở trang Promotions > Discounts, chưa nhập tiêu chí tìm kiếm Step: 1. Mở trang Discounts mới (chưa nhập gì) 2. Quan sát giá trị mặc định của từng trường | D13: 1. Hiển thị trang Discounts 2. Start date, End date hiển thị placeholder định dạng ngày; Coupon code, Discount name để trống; Discount type, Vendor, Is active đều là "All" | F13: Passed
A14: PROMO_DIS_View_06 | B14: Kiểm tra tooltip (?) của các trường tìm kiếm | C14: Pre-condition: + Đã đăng nhập trang admin demo (https://admin-demo.nopcommerce.com/admin/) + Đang ở trang Promotions > Discounts, chưa nhập tiêu chí tìm kiếm Step: 1. Rê chuột vào biểu tượng (?) cạnh từng nhãn trong khối Search | D14: 1. Mỗi biểu tượng hiển thị mô tả ngắn của trường, nội dung không bị cắt hoặc che khuất | F14: Passed
A15: PROMO_DIS_View_07 | B15: Kiểm tra thu gọn / mở rộng khối Search | C15: Pre-condition: + Đã đăng nhập trang admin demo (https://admin-demo.nopcommerce.com/admin/) + Đang ở trang Promotions > Discounts, chưa nhập tiêu chí tìm kiếm Step: 1. Nhập "sample" vào Discount name 2. Click mũi tên ở góc phải tiêu đề khối Search 3. Click mũi tên lần nữa | D15: 1. Discount name hiển thị "sample" 2. Khối Search được thu gọn, bảng kết quả vẫn hiển thị 3. Khối Search mở rộng lại, giá trị "sample" vẫn còn trong ô Discount name | F15: Passed
A16: PROMO_DIS_View_08 | B16: Kiểm tra các cột của bảng danh sách | C16: Pre-condition: + Đã đăng nhập trang admin demo (https://admin-demo.nopcommerce.com/admin/) + Đang ở trang Promotions > Discounts, chưa nhập tiêu chí tìm kiếm Step: 1. Quan sát bảng danh sách discount | D16: 1. Bảng có các cột Name, Discount type, Discount, Start date, End date, Times used, Is active, Edit; phía trên bảng có liên kết "Learn more about discounts" | F16: Passed
A17: PROMO_DIS_View_09 | B17: Kiểm tra dữ liệu mặc định trong bảng | C17: Pre-condition: + Đã đăng nhập trang admin demo (https://admin-demo.nopcommerce.com/admin/) + Đang ở trang Promotions > Discounts, chưa nhập tiêu chí tìm kiếm Step: 1. Quan sát các dòng trong bảng và thông tin phân trang | D17: 1. Hiển thị 2 dòng: "'20% order total' discount" (Assigned to order total, 20%, 11/04/2020 10:32:26 AM, 11/04/2030 10:32:26 AM, Times used 0, Is active có dấu ✓) và "Sample discount with coupon code" (Assigned to products, 10 USD, cùng Start date / End date, Times used 0, Is active có dấu ✓); thông tin phân trang "1-2 of 2 items" | F17: Passed | H17: Dữ liệu demo dùng chung, có thể bị reset hoặc bị người khác thêm/sửa; đối chiếu theo dữ liệu thực tế khi chạy
A18: PROMO_DIS_View_10 | B18: Kiểm tra định dạng cột Discount (phần trăm và số tiền) | C18: Pre-condition: + Đã đăng nhập trang admin demo (https://admin-demo.nopcommerce.com/admin/) + Đang ở trang Promotions > Discounts, chưa nhập tiêu chí tìm kiếm Step: 1. Quan sát giá trị cột Discount của 2 dòng | D18: 1. Discount dạng phần trăm hiển thị "20%"; discount dạng số tiền hiển thị kèm loại tiền "10 USD" | F18: Passed | H18: Dữ liệu demo dùng chung, có thể bị reset hoặc bị người khác thêm/sửa; đối chiếu theo dữ liệu thực tế khi chạy
A19: PROMO_DIS_View_11 | B19: Kiểm tra layout trang trên desktop và mobile | C19: Pre-condition: + Đã đăng nhập trang admin demo (https://admin-demo.nopcommerce.com/admin/) + Đang ở trang Promotions > Discounts, chưa nhập tiêu chí tìm kiếm Step: 1. Xem trang trên desktop 2. Thu nhỏ trình duyệt về kích thước mobile | D19: 1. Bố cục đúng, khối Search và bảng thẳng hàng, nút [Add new] hiển thị ở góc phải 2. Trang co giãn đúng, không vỡ giao diện; nút [Search], [Add new], [Edit] vẫn thao tác được | F19: Passed
A20: PROMO_DIS_Search_01 | B20: Kiểm tra tìm theo Discount name đầy đủ | C20: Pre-condition: + Đã đăng nhập trang admin demo (https://admin-demo.nopcommerce.com/admin/) + Đang ở trang Promotions > Discounts, chưa nhập tiêu chí tìm kiếm Step: 1. Nhập "'20% order total' discount" vào Discount name 2. Click [Search] | D20: 1. Dữ liệu được nhập đúng 2. Bảng chỉ còn 1 dòng "'20% order total' discount"; thông tin phân trang "1-1 of 1 items" | F20: Passed | H20: Dữ liệu demo dùng chung, có thể bị reset hoặc bị người khác thêm/sửa; đối chiếu theo dữ liệu thực tế khi chạy
A21: PROMO_DIS_Search_02 | B21: Kiểm tra tìm theo một phần Discount name | C21: Pre-condition: + Đã đăng nhập trang admin demo (https://admin-demo.nopcommerce.com/admin/) + Đang ở trang Promotions > Discounts, chưa nhập tiêu chí tìm kiếm Step: 1. Nhập "sample" (chữ thường) vào Discount name 2. Click [Search] | D21: 1. Dữ liệu được nhập đúng 2. Bảng chỉ còn 1 dòng "Sample discount with coupon code" (tìm theo chuỗi con, không phân biệt hoa thường) | F21: Passed | H21: Dữ liệu demo dùng chung, có thể bị reset hoặc bị người khác thêm/sửa; đối chiếu theo dữ liệu thực tế khi chạy; ghi nhận hành vi thực tế về phân biệt hoa thường
A22: PROMO_DIS_Search_03 | B22: Kiểm tra tìm Discount name không tồn tại | C22: Pre-condition: + Đã đăng nhập trang admin demo (https://admin-demo.nopcommerce.com/admin/) + Đang ở trang Promotions > Discounts, chưa nhập tiêu chí tìm kiếm Step: 1. Nhập "zzz_khong_ton_tai" vào Discount name 2. Click [Search] | D22: 1. Dữ liệu được nhập đúng 2. Bảng không có dòng dữ liệu, hiển thị thông báo không có dữ liệu; không báo lỗi hệ thống | F22: Passed | H22: Ghi nhận nội dung thông báo thực tế khi bảng rỗng
A23: PROMO_DIS_Search_04 | B23: Kiểm tra tìm theo Coupon code | C23: Pre-condition: + Đã đăng nhập trang admin demo (https://admin-demo.nopcommerce.com/admin/) + Đang ở trang Promotions > Discounts, chưa nhập tiêu chí tìm kiếm Step: 1. Click [Edit] ở dòng "Sample discount with coupon code", ghi lại giá trị Coupon code (không sửa gì), quay lại danh sách Discounts 2. Nhập Coupon code vừa ghi lại vào ô Coupon code 3. Click [Search] | D23: 1. Lấy được Coupon code, quay lại trang Discounts 2. Dữ liệu được nhập đúng 3. Bảng chỉ còn 1 dòng "Sample discount with coupon code" | F23: Passed | H23: Dữ liệu demo dùng chung, có thể bị reset hoặc bị người khác thêm/sửa; đối chiếu theo dữ liệu thực tế khi chạy
A24: PROMO_DIS_Search_05 | B24: Kiểm tra tìm Coupon code không tồn tại | C24: Pre-condition: + Đã đăng nhập trang admin demo (https://admin-demo.nopcommerce.com/admin/) + Đang ở trang Promotions > Discounts, chưa nhập tiêu chí tìm kiếm Step: 1. Nhập "NOTEXIST999" vào Coupon code 2. Click [Search] | D24: 1. Dữ liệu được nhập đúng 2. Bảng không có dòng dữ liệu, hiển thị thông báo không có dữ liệu; không báo lỗi hệ thống | F24: Passed
A25: PROMO_DIS_Search_06 | B25: Kiểm tra danh sách giá trị của Discount type | C25: Pre-condition: + Đã đăng nhập trang admin demo (https://admin-demo.nopcommerce.com/admin/) + Đang ở trang Promotions > Discounts, chưa nhập tiêu chí tìm kiếm Step: 1. Click ô chọn Discount type | D25: 1. Danh sách gồm "All" và các loại giảm giá như Assigned to order total, Assigned to products, Assigned to categories, Assigned to manufacturers, Assigned to order subtotal, Assigned to shipping | F25: Passed | H25: Đối chiếu danh sách thực tế với nopCommerce 4.90.4
A26: PROMO_DIS_Search_07 | B26: Kiểm tra lọc Discount type = Assigned to order total | C26: Pre-condition: + Đã đăng nhập trang admin demo (https://admin-demo.nopcommerce.com/admin/) + Đang ở trang Promotions > Discounts, chưa nhập tiêu chí tìm kiếm Step: 1. Chọn Discount type "Assigned to order total" 2. Click [Search] | D26: 1. Discount type hiển thị "Assigned to order total" 2. Bảng chỉ còn dòng "'20% order total' discount" | F26: Passed | H26: Dữ liệu demo dùng chung, có thể bị reset hoặc bị người khác thêm/sửa; đối chiếu theo dữ liệu thực tế khi chạy
A27: PROMO_DIS_Search_08 | B27: Kiểm tra lọc Discount type = Assigned to products | C27: Pre-condition: + Đã đăng nhập trang admin demo (https://admin-demo.nopcommerce.com/admin/) + Đang ở trang Promotions > Discounts, chưa nhập tiêu chí tìm kiếm Step: 1. Chọn Discount type "Assigned to products" 2. Click [Search] | D27: 1. Discount type hiển thị "Assigned to products" 2. Bảng chỉ còn dòng "Sample discount with coupon code" | F27: Failed | H27: Dữ liệu demo dùng chung, có thể bị reset hoặc bị người khác thêm/sửa; đối chiếu theo dữ liệu thực tế khi chạy
A28: PROMO_DIS_Search_09 | B28: Kiểm tra lọc Is active = Active only | C28: Pre-condition: + Đã đăng nhập trang admin demo (https://admin-demo.nopcommerce.com/admin/) + Đang ở trang Promotions > Discounts, chưa nhập tiêu chí tìm kiếm Step: 1. Click ô chọn Is active, quan sát danh sách giá trị 2. Chọn "Active only", click [Search] | D28: 1. Danh sách gồm "All", "Active only", "Inactive only" 2. Bảng chỉ hiển thị các discount đang active (cả 2 dòng mặc định đều có dấu ✓) | F28: Failed | H28: Dữ liệu demo dùng chung, có thể bị reset hoặc bị người khác thêm/sửa; đối chiếu theo dữ liệu thực tế khi chạy
A29: PROMO_DIS_Search_10 | B29: Kiểm tra lọc Is active = Inactive only | C29: Pre-condition: + Đã đăng nhập trang admin demo (https://admin-demo.nopcommerce.com/admin/) + Đang ở trang Promotions > Discounts, chưa nhập tiêu chí tìm kiếm Step: 1. Chọn Is active "Inactive only" 2. Click [Search] | D29: 1. Is active hiển thị "Inactive only" 2. Bảng không có dòng nào (2 discount mặc định đều đang active); không báo lỗi hệ thống | F29: Failed | H29: Dữ liệu demo dùng chung, có thể bị reset hoặc bị người khác thêm/sửa; đối chiếu theo dữ liệu thực tế khi chạy
A30: PROMO_DIS_Search_11 | B30: Kiểm tra lọc theo Start date | C30: Pre-condition: + Đã đăng nhập trang admin demo (https://admin-demo.nopcommerce.com/admin/) + Đang ở trang Promotions > Discounts, chưa nhập tiêu chí tìm kiếm Step: 1. Nhập Start date 01/01/2019, click [Search] 2. Đổi Start date thành 01/01/2025, click [Search] | D30: 1. Bảng hiển thị cả 2 discount (đều bắt đầu năm 2020, sau mốc đã chọn) 2. Bảng không có dòng nào vì cả 2 discount bắt đầu trước mốc đã chọn | F30: Passed | H30: Dữ liệu demo dùng chung, có thể bị reset hoặc bị người khác thêm/sửa; đối chiếu theo dữ liệu thực tế khi chạy; chọn mốc cách xa ngày bắt đầu để tránh nhầm định dạng ngày/tháng
A31: PROMO_DIS_Search_12 | B31: Kiểm tra lọc theo End date | C31: Pre-condition: + Đã đăng nhập trang admin demo (https://admin-demo.nopcommerce.com/admin/) + Đang ở trang Promotions > Discounts, chưa nhập tiêu chí tìm kiếm Step: 1. Nhập End date 31/12/2035, click [Search] 2. Đổi End date thành 01/01/2025, click [Search] | D31: 1. Bảng hiển thị cả 2 discount (đều kết thúc năm 2030, trước mốc đã chọn) 2. Bảng không có dòng nào vì cả 2 discount kết thúc sau mốc đã chọn | F31: Passed | H31: Dữ liệu demo dùng chung, có thể bị reset hoặc bị người khác thêm/sửa; đối chiếu theo dữ liệu thực tế khi chạy; chọn mốc cách xa ngày kết thúc để tránh nhầm định dạng ngày/tháng
A32: PROMO_DIS_Search_13 | B32: Kiểm tra lọc đồng thời Start date và End date | C32: Pre-condition: + Đã đăng nhập trang admin demo (https://admin-demo.nopcommerce.com/admin/) + Đang ở trang Promotions > Discounts, chưa nhập tiêu chí tìm kiếm Step: 1. Nhập Start date 01/01/2019 và End date 31/12/2035 2. Click [Search] | D32: 1. Dữ liệu được nhập đúng 2. Bảng hiển thị cả 2 discount nằm trong khoảng thời gian đã chọn | F32: Passed | H32: Dữ liệu demo dùng chung, có thể bị reset hoặc bị người khác thêm/sửa; đối chiếu theo dữ liệu thực tế khi chạy
A33: PROMO_DIS_Search_14 | B33: Kiểm tra Start date lớn hơn End date | C33: Pre-condition: + Đã đăng nhập trang admin demo (https://admin-demo.nopcommerce.com/admin/) + Đang ở trang Promotions > Discounts, chưa nhập tiêu chí tìm kiếm Step: 1. Nhập Start date 01/01/2035 và End date 01/01/2019 2. Click [Search] | D33: 1. Dữ liệu được nhập đúng 2. Bảng không có dòng nào; không báo lỗi hệ thống | F33: Passed | H33: Ghi nhận hành vi thực tế (có thể có thông báo lỗi hoặc chỉ trả về bảng rỗng)
A34: PROMO_DIS_Search_15 | B34: Kiểm tra bộ lọc Vendor | C34: Pre-condition: + Đã đăng nhập trang admin demo (https://admin-demo.nopcommerce.com/admin/) + Đang ở trang Promotions > Discounts, chưa nhập tiêu chí tìm kiếm Step: 1. Click ô chọn Vendor, quan sát danh sách 2. Chọn một vendor (nếu có), click [Search] | D34: 1. Danh sách gồm "All" và các vendor hiện có 2. Bảng chỉ hiển thị discount thuộc vendor đã chọn, hoặc không có dòng nào nếu vendor đó chưa có discount; không báo lỗi hệ thống | F34: Passed | H34: Dữ liệu demo dùng chung, có thể bị reset hoặc bị người khác thêm/sửa; đối chiếu theo dữ liệu thực tế khi chạy; ghi nhận hành vi thực tế vì demo có thể chỉ có giá trị "All"
A35: PROMO_DIS_Search_16 | B35: Kiểm tra kết hợp nhiều tiêu chí cho kết quả khớp | C35: Pre-condition: + Đã đăng nhập trang admin demo (https://admin-demo.nopcommerce.com/admin/) + Đang ở trang Promotions > Discounts, chưa nhập tiêu chí tìm kiếm Step: 1. Nhập Discount name "discount", chọn Discount type "Assigned to order total", chọn Is active "Active only" 2. Click [Search] | D35: 1. Các tiêu chí hiển thị đúng như đã chọn 2. Bảng chỉ còn dòng "'20% order total' discount" | F35: Failed | H35: Dữ liệu demo dùng chung, có thể bị reset hoặc bị người khác thêm/sửa; đối chiếu theo dữ liệu thực tế khi chạy
A36: PROMO_DIS_Search_17 | B36: Kiểm tra kết hợp nhiều tiêu chí không có kết quả | C36: Pre-condition: + Đã đăng nhập trang admin demo (https://admin-demo.nopcommerce.com/admin/) + Đang ở trang Promotions > Discounts, chưa nhập tiêu chí tìm kiếm Step: 1. Nhập Discount name "20%", chọn Discount type "Assigned to products" 2. Click [Search] | D36: 1. Các tiêu chí hiển thị đúng như đã chọn 2. Bảng không có dòng nào; không báo lỗi hệ thống | F36: Passed | H36: Dữ liệu demo dùng chung, có thể bị reset hoặc bị người khác thêm/sửa; đối chiếu theo dữ liệu thực tế khi chạy
... A45: PROMO_DIS_Page_04 | B45: Kiểm tra nút làm mới bảng (biểu tượng refresh) | C45: Pre-condition: + Đã đăng nhập trang admin demo (https://admin-demo.nopcommerce.com/admin/) + Đang ở trang Promotions > Discounts, chưa nhập tiêu chí tìm kiếm Step: 1. Nhập Discount name "sample", click [Search] 2. Click nút làm mới ở góc phải dưới bảng | D45: 1. Bảng chỉ còn 1 dòng 2. Bảng tải lại, vẫn áp dụng tiêu chí đang nhập (1 dòng); không báo lỗi hệ thống | F45: Passed | H45: Dữ liệu demo dùng chung, có thể bị reset hoặc bị người khác thêm/sửa; đối chiếu theo dữ liệu thực tế khi chạy; ghi nhận bộ lọc có được giữ khi làm mới hay không
A46: PROMO_DIS_Nav_01 | B46: Kiểm tra nút [Add new] | C46: Pre-condition: + Đã đăng nhập trang admin demo (https://admin-demo.nopcommerce.com/admin/) + Đang ở trang Promotions > Discounts, chưa nhập tiêu chí tìm kiếm Step: 1. Click [Add new] ở góc phải trên cùng | D46: 1. Chuyển sang trang thêm discount mới (URL /Admin/Discount/Create); không tạo discount nào | F46: Passed
A47: PROMO_DIS_Nav_02 | B47: Kiểm tra nút [Edit] và quay lại danh sách | C47: Pre-condition: + Đã đăng nhập trang admin demo (https://admin-demo.nopcommerce.com/admin/) + Đang ở trang Promotions > Discounts, chưa nhập tiêu chí tìm kiếm Step: 1. Click [Edit] ở dòng "'20% order total' discount" 2. Click liên kết quay lại danh sách discount (back to discount list) | D47: 1. Mở trang Edit discount, tên discount đúng với dòng đã chọn 2. Quay lại trang Discounts, bảng vẫn hiển thị danh sách discount | F47: Passed | H47: Dữ liệu demo dùng chung, có thể bị reset hoặc bị người khác thêm/sửa; đối chiếu theo dữ liệu thực tế khi chạy
A48: PROMO_DIS_Nav_03 | B48: Kiểm tra chuyển qua lại giữa các mục trong menu Promotions | C48: Pre-condition: + Đã đăng nhập trang admin demo (https://admin-demo.nopcommerce.com/admin/) + Đang ở trang Promotions > Discounts, chưa nhập tiêu chí tìm kiếm Step: 1. Click [Affiliates] trong menu Promotions 2. Click [Discounts] | D48: 1. Hiển thị trang Affiliates 2. Hiển thị lại trang Discounts, mục Discounts được làm nổi bật trong menu | F48: Passed
A49: PROMO_DIS_Nav_04 | B49: Kiểm tra liên kết "Learn more about discounts" | C49: Pre-condition: + Đã đăng nhập trang admin demo (https://admin-demo.nopcommerce.com/admin/) + Đang ở trang Promotions > Discounts, chưa nhập tiêu chí tìm kiếm Step: 1. Click liên kết "discounts" trong dòng "Learn more about discounts" | D49: 1. Mở trang tài liệu nopCommerce về discounts (docs.nopcommerce.com); trang admin vẫn giữ nguyên | F49: Passed | H49: Ghi nhận trang tài liệu mở ở tab mới hay cùng tab
A50: PROMO_DIS_Nav_05 | B50: Kiểm tra tải lại trang (F5) sau khi tìm kiếm | C50: Pre-condition: + Đã đăng nhập trang admin demo (https://admin-demo.nopcommerce.com/admin/) + Đang ở trang Promotions > Discounts, chưa nhập tiêu chí tìm kiếm Step: 1. Nhập Discount name "sample", click [Search] 2. Nhấn F5 | D50: 1. Bảng chỉ còn 1 dòng 2. Trang tải lại, không báo lỗi hệ thống; ghi nhận bộ lọc được giữ hay trở về mặc định | F50: Failed | H50: Ghi nhận hành vi thực tế sau khi tải lại trang
...

Sheet Admin - Promotions - Affiliates
A2: Module Code | B2: Admin - Promotions - Affiliates | J2: Passed
A3: Test requirement | B3: Affiliates (Promotions > Affiliates): danh sách affiliate trên trang admin | J3: Failed
A4: Tester | B4: Lê Hữu Phước | J4: Blocked
A5: Passed | B5: Failed | C5: Untested | D5: Blocked | E5: Skipped | F5: Number of Test cases | J5: Untested
A6: =COUNTIF(F9:F996,"Passed") -> 0 | B6: =COUNTIF(F9:F996,"Failed") -> 0 | C6: =F6-E6-D6-B6-A6 -> 42 | D6: =COUNTIF(F$9:F$996,"Blocked") -> 0 | E6: =COUNTIF(F$9:F$996,"Skipped") -> 0 | F6: =COUNTA(A9:A996) -> 42 | J6: Skipped
A8: ID | B8: Test Case Description | C8: Test Case Procedure | D8: Expected Output | E8: Inter-test case Dependence | F8: Result | G8: Test date | H8: Note
A9: PROMO_AFF_View_01 | B9: Kiểm tra mở trang Affiliates từ menu Promotions | C9: Pre-condition: + Đã đăng nhập trang admin demo (https://admin-demo.nopcommerce.com/admin/) + Đang ở trang Dashboard Step: 1. Click menu [Promotions] ở thanh bên trái 2. Click [Affiliates] | D9: 1. Menu Promotions mở rộng, gồm Discounts, Affiliates, Newsletter subscribers, Subscription types, Campaigns 2. Hiển thị trang Affiliates (URL /Admin/Affiliate/List), mục Affiliates được làm nổi bật trong menu, tiêu đề trang là "Affiliates"
A10: PROMO_AFF_View_02 | B10: Kiểm tra truy cập trực tiếp bằng URL /Admin/Affiliate/List | C10: Pre-condition: + Đã đăng nhập trang admin demo (https://admin-demo.nopcommerce.com/admin/) Step: 1. Nhập URL https://admin-demo.nopcommerce.com/Admin/Affiliate/List vào thanh địa chỉ 2. Quan sát header và menu bên trái | D10: 1. Hiển thị trang Affiliates 2. Header có tên tài khoản và [Logout]; menu Promotions mở sẵn và mục Affiliates được chọn
A11: PROMO_AFF_View_03 | B11: Kiểm tra đoạn giới thiệu phía trên bảng danh sách | C11: Pre-condition: + Đã đăng nhập trang admin demo (https://admin-demo.nopcommerce.com/admin/) + Đang ở trang Promotions > Affiliates, chưa nhập tiêu chí tìm kiếm Step: 1. Quan sát phần nội dung phía trên bảng danh sách | D11: 1. Hiển thị đoạn giải thích về affiliate (bắt đầu bằng "Affiliate is an Internet-based marketing practice...") và liên kết "affiliates" ở cuối đoạn; nội dung không bị cắt hoặc chồng lấn
A12: PROMO_AFF_View_04 | B12: Kiểm tra trạng thái mặc định và thu gọn / mở rộng khối Search | C12: Pre-condition: + Đã đăng nhập trang admin demo (https://admin-demo.nopcommerce.com/admin/) + Đang ở trang Promotions > Affiliates, chưa nhập tiêu chí tìm kiếm Step: 1. Quan sát khối Search khi vừa mở trang 2. Click mũi tên ở góc phải tiêu đề khối Search 3. Click mũi tên lần nữa | D12: 1. Khối Search đang thu gọn (chỉ có tiêu đề Search và mũi tên), bảng danh sách hiển thị bên dưới 2. Khối Search mở rộng, hiển thị các trường tìm kiếm và nút [Search] 3. Khối Search thu gọn lại, bảng danh sách vẫn hiển thị | H12: Trong ảnh chụp ban đầu khối Search đang thu gọn; ghi nhận trạng thái mặc định thực tế (trạng thái đóng/mở có thể được trình duyệt nhớ theo lần thao tác trước)
A13: PROMO_AFF_View_05 | B13: Kiểm tra các trường và nút trong khối Search | C13: Pre-condition: + Đã đăng nhập trang admin demo (https://admin-demo.nopcommerce.com/admin/) + Đang ở trang Promotions > Affiliates, chưa nhập tiêu chí tìm kiếm Step: 1. Click mũi tên để mở rộng khối Search nếu đang thu gọn 2. Quan sát các trường và nút trong khối Search | D13: 1. Khối Search mở rộng 2. Khối Search có các ô nhập First name, Last name, Friendly URL name, ô tích Load only with orders và nút [Search]; mỗi nhãn có biểu tượng (?)
A14: PROMO_AFF_View_06 | B14: Kiểm tra giá trị mặc định của khối Search | C14: Pre-condition: + Đã đăng nhập trang admin demo (https://admin-demo.nopcommerce.com/admin/) + Đang ở trang Promotions > Affiliates, chưa nhập tiêu chí tìm kiếm Step: 1. Mở trang Affiliates mới (chưa nhập gì) 2. Mở rộng khối Search, quan sát giá trị các trường | D14: 1. Hiển thị trang Affiliates 2. Các ô nhập First name, Last name, Friendly URL name đều để trống; ô Load only with orders chưa được tích
A15: PROMO_AFF_View_07 | B15: Kiểm tra tooltip (?) của các trường tìm kiếm | C15: Pre-condition: + Đã đăng nhập trang admin demo (https://admin-demo.nopcommerce.com/admin/) + Đang ở trang Promotions > Affiliates, chưa nhập tiêu chí tìm kiếm Step: 1. Mở rộng khối Search 2. Rê chuột vào biểu tượng (?) cạnh từng nhãn | D15: 1. Khối Search mở rộng 2. Mỗi biểu tượng hiển thị mô tả ngắn của trường, nội dung không bị cắt hoặc che khuất
A16: PROMO_AFF_View_08 | B16: Kiểm tra các cột của bảng danh sách | C16: Pre-condition: + Đã đăng nhập trang admin demo (https://admin-demo.nopcommerce.com/admin/) + Đang ở trang Promotions > Affiliates, chưa nhập tiêu chí tìm kiếm Step: 1. Quan sát bảng danh sách | D16: 1. Bảng có các cột First name, Last name, Active, Edit; phía trên bảng có liên kết "Learn more about affiliates"
A17: PROMO_AFF_View_09 | B17: Kiểm tra dữ liệu mặc định trong bảng | C17: Pre-condition: + Đã đăng nhập trang admin demo (https://admin-demo.nopcommerce.com/admin/) + Đang ở trang Promotions > Affiliates, chưa nhập tiêu chí tìm kiếm Step: 1. Quan sát các dòng trong bảng và thông tin phân trang | D17: 1. Hiển thị 1 dòng: John Smith (Active có dấu ✓, có nút [Edit]); thông tin phân trang "1-1 of 1 items" | H17: Dữ liệu demo dùng chung, có thể bị reset hoặc bị người khác thêm/sửa; đối chiếu theo dữ liệu thực tế khi chạy
A18: PROMO_AFF_View_10 | B18: Kiểm tra layout trang trên desktop và mobile | C18: Pre-condition: + Đã đăng nhập trang admin demo (https://admin-demo.nopcommerce.com/admin/) + Đang ở trang Promotions > Affiliates, chưa nhập tiêu chí tìm kiếm Step: 1. Xem trang trên desktop 2. Thu nhỏ trình duyệt về kích thước mobile | D18: 1. Bố cục đúng, khối Search và bảng thẳng hàng, nút [Add new] hiển thị ở góc phải 2. Trang co giãn đúng, không vỡ giao diện; nút [Search], [Add new], [Edit] vẫn thao tác được
A19: PROMO_AFF_Search_01 | B19: Kiểm tra tìm theo First name đầy đủ | C19: Pre-condition: + Đã đăng nhập trang admin demo (https://admin-demo.nopcommerce.com/admin/) + Đang ở trang Promotions > Affiliates, khối Search đang mở rộng, chưa nhập tiêu chí tìm kiếm Step: 1. Nhập "John" vào First name 2. Click [Search] | D19: 1. Dữ liệu được nhập đúng 2. Bảng chỉ còn 1 dòng John Smith; thông tin phân trang "1-1 of 1 items" | H19: Dữ liệu demo dùng chung, có thể bị reset hoặc bị người khác thêm/sửa; đối chiếu theo dữ liệu thực tế khi chạy
A20: PROMO_AFF_Search_02 | B20: Kiểm tra tìm theo Last name đầy đủ | C20: Pre-condition: + Đã đăng nhập trang admin demo (https://admin-demo.nopcommerce.com/admin/) + Đang ở trang Promotions > Affiliates, khối Search đang mở rộng, chưa nhập tiêu chí tìm kiếm Step: 1. Nhập "Smith" vào Last name 2. Click [Search] | D20: 1. Dữ liệu được nhập đúng 2. Bảng chỉ còn 1 dòng John Smith; thông tin phân trang "1-1 of 1 items" | H20: Dữ liệu demo dùng chung, có thể bị reset hoặc bị người khác thêm/sửa; đối chiếu theo dữ liệu thực tế khi chạy
A21: PROMO_AFF_Search_03 | B21: Kiểm tra tìm theo một phần First name | C21: Pre-condition: + Đã đăng nhập trang admin demo (https://admin-demo.nopcommerce.com/admin/) + Đang ở trang Promotions > Affiliates, khối Search đang mở rộng, chưa nhập tiêu chí tìm kiếm Step: 1. Nhập "joh" (chữ thường) vào First name 2. Click [Search] | D21: 1. Dữ liệu được nhập đúng 2. Bảng hiển thị dòng John Smith (tìm theo chuỗi con, không phân biệt hoa thường) | H21: Dữ liệu demo dùng chung, có thể bị reset hoặc bị người khác thêm/sửa; đối chiếu theo dữ liệu thực tế khi chạy; ghi nhận hành vi thực tế về phân biệt hoa thường
A22: PROMO_AFF_Search_04 | B22: Kiểm tra tìm theo một phần Last name | C22: Pre-condition: + Đã đăng nhập trang admin demo (https://admin-demo.nopcommerce.com/admin/) + Đang ở trang Promotions > Affiliates, khối Search đang mở rộng, chưa nhập tiêu chí tìm kiếm Step: 1. Nhập "mit" vào Last name 2. Click [Search] | D22: 1. Dữ liệu được nhập đúng 2. Bảng hiển thị dòng John Smith (tìm theo chuỗi con) | H22: Dữ liệu demo dùng chung, có thể bị reset hoặc bị người khác thêm/sửa; đối chiếu theo dữ liệu thực tế khi chạy; ghi nhận hành vi thực tế về tìm theo chuỗi con
A23: PROMO_AFF_Search_05 | B23: Kiểm tra tìm đồng thời First name và Last name khớp nhau | C23: Pre-condition: + Đã đăng nhập trang admin demo (https://admin-demo.nopcommerce.com/admin/) + Đang ở trang Promotions > Affiliates, khối Search đang mở rộng, chưa nhập tiêu chí tìm kiếm Step: 1. Nhập "John" vào First name và "Smith" vào Last name 2. Click [Search] | D23: 1. Dữ liệu được nhập đúng 2. Bảng chỉ còn 1 dòng John Smith | H23: Dữ liệu demo dùng chung, có thể bị reset hoặc bị người khác thêm/sửa; đối chiếu theo dữ liệu thực tế khi chạy
A24: PROMO_AFF_Search_06 | B24: Kiểm tra tìm đồng thời First name và Last name không khớp nhau | C24: Pre-condition: + Đã đăng nhập trang admin demo (https://admin-demo.nopcommerce.com/admin/) + Đang ở trang Promotions > Affiliates, khối Search đang mở rộng, chưa nhập tiêu chí tìm kiếm Step: 1. Nhập "John" vào First name và "Doe" vào Last name 2. Click [Search] | D24: 1. Dữ liệu được nhập đúng 2. Bảng không có dòng nào; không báo lỗi hệ thống | H24: Dữ liệu demo dùng chung, có thể bị reset hoặc bị người khác thêm/sửa; đối chiếu theo dữ liệu thực tế khi chạy
A25: PROMO_AFF_Search_07 | B25: Kiểm tra tìm First name không tồn tại | C25: Pre-condition: + Đã đăng nhập trang admin demo (https://admin-demo.nopcommerce.com/admin/) + Đang ở trang Promotions > Affiliates, khối Search đang mở rộng, chưa nhập tiêu chí tìm kiếm Step: 1. Nhập "zzz_khong_ton_tai" vào First name 2. Click [Search] | D25: 1. Dữ liệu được nhập đúng 2. Bảng không có dòng dữ liệu, hiển thị thông báo không có dữ liệu; không báo lỗi hệ thống | H25: Ghi nhận nội dung thông báo thực tế khi bảng rỗng
A26: PROMO_AFF_Search_08 | B26: Kiểm tra tìm theo Friendly URL name | C26: Pre-condition: + Đã đăng nhập trang admin demo (https://admin-demo.nopcommerce.com/admin/) + Đang ở trang Promotions > Affiliates, chưa nhập tiêu chí tìm kiếm Step: 1. Click [Edit] ở dòng John Smith, ghi lại giá trị Friendly URL name (không sửa gì), quay lại danh sách Affiliates 2. Mở rộng khối Search nếu cần, nhập Friendly URL name vừa ghi lại vào ô Friendly URL name 3. Click [Search] | D26: 1. Lấy được Friendly URL name, quay lại trang Affiliates 2. Dữ liệu được nhập đúng 3. Bảng chỉ còn 1 dòng John Smith | H26: Dữ liệu demo dùng chung, có thể bị reset hoặc bị người khác thêm/sửa; đối chiếu theo dữ liệu thực tế khi chạy; nếu Friendly URL name của affiliate đang rỗng thì ghi nhận Skipped
A27: PROMO_AFF_Search_09 | B27: Kiểm tra tìm Friendly URL name không tồn tại | C27: Pre-condition: + Đã đăng nhập trang admin demo (https://admin-demo.nopcommerce.com/admin/) + Đang ở trang Promotions > Affiliates, khối Search đang mở rộng, chưa nhập tiêu chí tìm kiếm Step: 1. Nhập "NOTEXIST999" vào Friendly URL name 2. Click [Search] | D27: 1. Dữ liệu được nhập đúng 2. Bảng không có dòng dữ liệu, hiển thị thông báo không có dữ liệu; không báo lỗi hệ thống
A28: PROMO_AFF_Search_10 | B28: Kiểm tra lọc affiliate có đơn hàng (Load only with orders) | C28: Pre-condition: + Đã đăng nhập trang admin demo (https://admin-demo.nopcommerce.com/admin/) + Đang ở trang Promotions > Affiliates, khối Search đang mở rộng, chưa nhập tiêu chí tìm kiếm Step: 1. Tích ô Load only with orders 2. Click [Search] | D28: 1. Ô được tích 2. Bảng chỉ hiển thị affiliate có đơn hàng phát sinh, hoặc không có dòng nào nếu John Smith chưa có đơn; không báo lỗi hệ thống | H28: Dữ liệu demo dùng chung, có thể bị reset hoặc bị người khác thêm/sửa; đối chiếu theo dữ liệu thực tế khi chạy; ghi nhận kết quả thực tế vì affiliate mặc định có thể chưa có đơn hàng
A29: PROMO_AFF_Search_11 | B29: Kiểm tra bỏ trống toàn bộ tiêu chí rồi click [Search] | C29: Pre-condition: + Đã đăng nhập trang admin demo (https://admin-demo.nopcommerce.com/admin/) + Đang ở trang Promotions > Affiliates, khối Search đang mở rộng, chưa nhập tiêu chí tìm kiếm Step: 1. Không nhập tiêu chí nào 2. Click [Search] | D29: 1. Các ô đều trống 2. Bảng hiển thị đủ danh sách affiliate (1 dòng mặc định); không báo lỗi hệ thống | H29: Dữ liệu demo dùng chung, có thể bị reset hoặc bị người khác thêm/sửa; đối chiếu theo dữ liệu thực tế khi chạy
A30: PROMO_AFF_Search_12 | B30: Kiểm tra xóa tiêu chí rồi tìm lại | C30: Pre-condition: + Đã đăng nhập trang admin demo (https://admin-demo.nopcommerce.com/admin/) + Đang ở trang Promotions > Affiliates, khối Search đang mở rộng, chưa nhập tiêu chí tìm kiếm Step: 1. Nhập "John" vào First name, click [Search] 2. Xóa nội dung First name, click [Search] | D30: 1. Bảng chỉ còn 1 dòng 2. Bảng hiển thị lại đủ danh sách affiliate (1 dòng mặc định) | H30: Dữ liệu demo dùng chung, có thể bị reset hoặc bị người khác thêm/sửa; đối chiếu theo dữ liệu thực tế khi chạy
A31: PROMO_AFF_Search_13 | B31: Kiểm tra tìm kiếm bằng phím Enter | C31: Pre-condition: + Đã đăng nhập trang admin demo (https://admin-demo.nopcommerce.com/admin/) + Đang ở trang Promotions > Affiliates, khối Search đang mở rộng, chưa nhập tiêu chí tìm kiếm Step: 1. Nhập "John" vào First name 2. Nhấn phím Enter | D31: 1. Dữ liệu được nhập đúng 2. Thực hiện tìm kiếm như khi click [Search] (hoặc không phản hồi - ghi nhận hành vi thực tế) | H31: Ghi nhận hành vi thực tế của phím Enter trong ô First name
A32: PROMO_AFF_Search_14 | B32: Kiểm tra First name có khoảng trắng đầu cuối | C32: Pre-condition: + Đã đăng nhập trang admin demo (https://admin-demo.nopcommerce.com/admin/) + Đang ở trang Promotions > Affiliates, khối Search đang mở rộng, chưa nhập tiêu chí tìm kiếm Step: 1. Nhập " John " (có khoảng trắng đầu và cuối) vào First name 2. Click [Search] | D32: 1. Dữ liệu được nhập đúng 2. Hệ thống cắt khoảng trắng và hiển thị kết quả của "John", hoặc không có kết quả (ghi nhận hành vi thực tế); không báo lỗi hệ thống | H32: Ghi nhận hành vi thực tế khi có khoảng trắng đầu/cuối
