Workbook

Sheet Cover
B2: TEST CASE SPECIFICATION
B4: Project Name | C4: nopCommerce - Admin Sales Management | F4: Creator | G4: Trương Cao Đoàn
B5: Project Code | C5: NOP-SALES-2026 | F5: Reviewer/Approver | G5: ThS. Trần Thị Thanh Nga
B6: Document Code | C6: NOP-SALES_TestCase_V1.0 | F6: Issue Date | G6: 2026-10-21
B7: AUT (URL) | C7: https://admin-demo.nopcommerce.com/Admin | F7: Version | G7: 1.0
B10: Record of change
B11: Effective Date | C11: Version | D11: Change Item | E11: *A,D,M | F11: Change description | G11: Reference
B12: 2026-10-21 | C12: 1.2 | E12: A | F12: Thực hiện automatio danh sách test case của module quản lý thẻ quà tặng admin_giftcard

Sheet Test case List
B2: TEST CASE LIST
B4: Project Name | D4: nopCommerce Admin Sales Management
B5: Project Code | D5: NOP-SALES-2026
B6: Test Environment Setup Description | D6: 1. Server: ASP.NET Core E-commerce Server 2. Database: MS SQL Server / SQLite Demo DB 3. Trình duyệt web: Google Chrome (Bản mới nhất) 4. Phân hệ Admin: https://admin-demo.nopcommerce.com/Admin 5. Tài khoản quản trị: admin@yourstore.com / admin
B8: No | C8: Function Name | D8: Sheet Name | E8: Description | F8: Pre-Condition
B9: 1 | C9: Quản lý Đơn hàng (Orders) | D9: Admin - Orders | E9: Kiểm thử tìm kiếm, lọc theo ngày/trạng thái, chi tiết, thay đổi tổng tiền, thêm sản phẩm, đổi trạng thái và xuất dữ liệu (44 TCs) | F9: Đăng nhập với tài khoản Quản trị viên (Admin)
B10: 2 | C10: Quản lý Giao hàng (Shipments) | D10: Admin - Shipments | E10: Kiểm thử danh sách chuyến hàng, lọc theo mã vận đơn/quốc gia/ngày xuất kho, cập nhật shipped/delivered (20 TCs) | F10: Đăng nhập với tài khoản Quản trị viên (Admin)
B11: 3 | C11: Quản lý Thẻ quà tặng (Gift cards) | D11: Admin - Gift cards | E11: Kiểm thử danh sách, sinh mã tự động, thêm mới thẻ quà tặng và kích hoạt/vô hiệu hóa thẻ (20 TCs) | F11: Đăng nhập với tài khoản Quản trị viên (Admin)

Sheet TestDesign
A1: Requirement Level 1 | B1: Requirement Level 2 | C1: Requirement Level 3 | D1: Test Criteria | E1: Test Type | F1: Note
A2: 1. Quản lý bán hàng (Admin - Sales) | B2: 1.1 Orders (Đơn hàng) | C2: Hiển thị | D2: Kiểm tra hiển thị màn hình danh sách đơn hàng khi click [Sales > Orders] | E2: GUI
D3: Kiểm tra trạng thái hiển thị mặc định của bảng đơn hàng | E3: GUI
D4: Kiểm tra bố cục và các cột dữ liệu (Mã đơn, Trạng thái đơn, Trạng thái thanh toán, Trạng thái giao hàng, Khách hàng, Cửa hàng, Ngày tạo, Tổng tiền, Nút xem) | E4: GUI
C5: Lọc theo ngày | D5: Kiểm tra lọc với Từ ngày và Đến ngày hợp lệ (Từ ngày <= Đến ngày) | E5: Function
D6: Kiểm tra lọc với Từ ngày > Đến ngày | E6: Function
D7: Kiểm tra lọc khi chỉ nhập Từ ngày | E7: Function
D8: Kiểm tra lọc khi chỉ nhập Đến ngày | E8: Function
C9: Lọc theo trạng thái | D9: Kiểm tra lọc theo Trạng thái đơn hàng = 'Pending' | E9: Function
D10: Kiểm tra lọc theo Trạng thái đơn hàng = 'Processing' | E10: Function
D11: Kiểm tra lọc theo Trạng thái đơn hàng = 'Complete' | E11: Function
D12: Kiểm tra lọc theo Trạng thái đơn hàng = 'Cancelled' | E12: Function
D13: Kiểm tra lọc theo Trạng thái thanh toán = 'Pending' | E13: Function
D14: Kiểm tra lọc theo Trạng thái thanh toán = 'Authorized' | E14: Function
D15: Kiểm tra lọc theo Trạng thái thanh toán = 'Paid' | E15: Function
D16: Kiểm tra lọc theo Trạng thái thanh toán = 'Refunded' | E16: Function
D17: Kiểm tra lọc theo Trạng thái thanh toán = 'Void' | E17: Function
D18: Kiểm tra lọc theo Trạng thái thanh toán = 'Partially Refunded' | E18: Function
D19: Kiểm tra lọc theo Trạng thái giao hàng = 'Not yet shipped' | E19: Function
D20: Kiểm tra lọc theo Trạng thái giao hàng = 'Shipped' | E20: Function
D21: Kiểm tra lọc theo Trạng thái giao hàng = 'Delivered' | E21: Function
C22: Tìm kiếm theo trường | D22: Kiểm tra tìm kiếm theo Email thanh toán với email đang tồn tại trong hệ thống | E22: Function
D23: Kiểm tra tìm kiếm theo Email thanh toán với sai cú pháp email | E23: Function
D24: Kiểm tra tìm kiếm theo Tên khách hàng (Billing Last Name) | E24: Function
D25: Kiểm tra tìm kiếm theo từ khóa trong Ghi chú đơn hàng (Order notes) | E25: Function
C26: Phân trang | D26: Kiểm tra chuyển sang trang kế tiếp | E26: Function
D27: Kiểm tra quay lại trang trước đó | E27: Function
D28: Kiểm tra thay đổi số lượng bản ghi hiển thị trên trang (15, 20, 50, 100 dòng/trang) | E28: Function
C29: Chi tiết đơn hàng | D29: Kiểm tra điều hướng vào trang Chi tiết đơn hàng khi click nút [View] | E29: Function
D30: Kiểm tra bố cục trang Chi tiết đơn hàng (tab Thông tin chung, Địa chỉ, Danh sách sản phẩm, Ghi chú) | E30: GUI
C31: Thay đổi tổng tiền của đơn hàng | D31: Kiểm tra thay đổi tổng tiền đơn hàng với số âm | E31: Function
D32: Kiểm tra thay đổi tổng tiền của đơn hàng với số tiền cực lớn | E32: Function
D33: Kiểm tra thay đổi tổng tiền của đơn hàng với số tiền thực tế | E33: Function
C34: Đổi trạng thái đơn | D34: Kiểm tra cập nhật trạng thái đơn hàng từ 'Pending' sang 'Processing' | E34: Function
D35: Kiểm tra cập nhật trạng thái đơn hàng từ 'Processing' sang 'Complete' | E35: Function
D36: Kiểm tra hủy đơn hàng và chuyển trạng thái sang 'Cancelled' | E36: Function
C37: Ghi chú đơn hàng | D37: Kiểm tra thêm ghi chú đơn hàng có chọn 'Display to customer' | E37: Function
D38: Kiểm tra thêm ghi chú đơn hàng không chọn 'Display to customer' | E38: Function
D39: Kiểm tra xóa một ghi chú đơn hàng | E39: Function
C40: Xuất dữ liệu & In ấn | D40: Kiểm tra xuất các đơn hàng đã chọn ra tệp Excel (.xlsx) | E40: Function
...

Sheet Admin - Orders
A2: Module Code | B2: Admin_Orders
A3: Test requirement | B3: Quản lý Đơn hàng (Admin - Orders)
A4: Tester | B4: Trương Cao Đoàn
A5: Passed | B5: Failed | C5: Untested | D5: Blocked | E5: Skipped | F5: Number of Test cases
A6: =COUNTIF(F9:F52, "Passed") -> 37 | B6: =COUNTIF(F9:F52, "Failed") -> 5 | C6: =COUNTBLANK(F9:F52) + COUNTIF(F9:F52, "Untested") -> 0 | D6: =COUNTIF(F9:F52, "Blocked") -> 2 | E6: =COUNTIF(F9:F52, "Skipped") -> 0 | F6: =COUNTA(A9:A52) -> 44
A8: ID | B8: Test Case Description | C8: Test Case Procedure | D8: Expected Output | E8: Inter-test case Dependence | F8: Result | G8: Test date | H8: Note
A9: admin_ord_01 | B9: Kiểm tra hiển thị màn hình danh sách đơn hàng khi click [admin > Orders] | C9: Pre-condition: + Đăng nhập tài khoản Quản trị viên (Admin). Step: 1. Tại thanh menu bên trái, click chọn [admin] 2. Click chọn mục con [Orders] | D9: 1. Màn hình Quản lý đơn hàng hiển thị chính xác. 2. Khung lọc tìm kiếm, các nút chức năng và bảng dữ liệu hiển thị đúng chuẩn GUI. | E9: None | F9: Passed | G9: 46323
A10: admin_ord_02 | B10: Kiểm tra trạng thái hiển thị mặc định của bảng đơn hàng | C10: Step: 1. Mở màn hình Orders 2. Quan sát các tiêu chí lọc mặc định và bảng danh sách | D10: 1. Các dropdown trạng thái hiển thị mặc định là 'All'. 2. Bảng dữ liệu hiển thị danh sách toàn bộ các đơn hàng hiện có trong hệ thống. | E10: admin_ord_01 | F10: Passed | G10: 46324
A11: admin_ord_03 | B11: Kiểm tra bố cục và các cột dữ liệu trên bảng đơn hàng | C11: Step: 1. Quan sát hàng tiêu đề của bảng dữ liệu đơn hàng | D11: 1. Bảng hiển thị đầy đủ các cột: Mã đơn (Order #), Trạng thái đơn (Order status), Trạng thái thanh toán (Payment status), Trạng thái giao hàng (Shipping status), Khách hàng (Customer), Cửa hàng (Store), Ngày tạo (Created on), Tổng tiền (Order total), Nút xem (View). | E11: admin_ord_01 | F11: Passed | G11: 46325
A12: admin_ord_04 | B12: Kiểm tra lọc đơn hàng với khoảng ngày hợp lệ (Từ ngày <= Đến ngày) | C12: Step: 1. Chọn Start date = '2026-10-01' 2. Chọn End date = '2026-10-20' 3. Click nút [Search] | D12: 1. Danh sách chỉ hiển thị các đơn hàng được tạo trong khoảng từ 2026-10-01 00:00:00 đến 2026-10-20 23:59:59. | E12: admin_ord_01 | F12: Failed | G12: 46326
A13: admin_ord_05 | B13: Kiểm tra lọc đơn hàng với khoảng ngày không hợp lệ (Từ ngày > Đến ngày) | C13: Step: 1. Chọn Start date = '2026-10-20' 2. Chọn End date = '2026-10-01' 3. Click nút [Search] | D13: 1. Hệ thống hiển thị cảnh báo khoảng ngày không hợp lệ. 2. Bảng dữ liệu hiển thị 'No data available in table'. | E13: admin_ord_01 | F13: Failed | G13: 46327 | H13: Lỗi do thực tế không thông báo định dạng email bị sai
A14: admin_ord_06 | B14: Kiểm tra lọc đơn hàng khi chỉ nhập Từ ngày (Start date) | C14: Step: 1. Nhập Start date = '2026-10-01' 2. Để trống End date 3. Click nút [Search] | D14: 1. Danh sách hiển thị tất cả các đơn hàng được tạo từ ngày 2026-10-01 trở về sau. | E14: admin_ord_01 | F14: Passed | G14: 46328
A15: admin_ord_07 | B15: Kiểm tra lọc đơn hàng khi chỉ nhập Đến ngày (End date) | C15: Step: 1. Để trống Start date 2. Nhập End date = '2026-10-20' 3. Click nút [Search] | D15: 1. Danh sách hiển thị tất cả các đơn hàng được tạo trước hoặc trong ngày 2026-10-20. | E15: admin_ord_01 | F15: Passed | G15: 46329
A16: admin_ord_08 | B16: Kiểm tra lọc đơn hàng theo Order status = 'Pending' | C16: Step: 1. Chọn Order status = [Pending] 2. Click nút [Search] | D16: 1. Bảng dữ liệu chỉ lọc các đơn hàng có trạng thái là 'Pending'. | E16: admin_ord_01 | F16: Passed | G16: 46330
A17: admin_ord_09 | B17: Kiểm tra lọc đơn hàng theo Order status = 'Processing' | C17: Step: 1. Chọn Order status = [Processing] 2. Click nút [Search] | D17: 1. Bảng dữ liệu chỉ hiển thị các đơn hàng đang xử lý có trạng thái 'Processing'. | E17: admin_ord_01 | F17: Passed | G17: 46331
A18: admin_ord_10 | B18: Kiểm tra lọc đơn hàng theo Order status = 'Complete' | C18: Step: 1. Chọn Order status = [Complete] 2. Click nút [Search] | D18: 1. Bảng dữ liệu chỉ hiển thị các đơn hàng đã hoàn tất (Complete) với nhãn màu xanh lá. | E18: admin_ord_01 | F18: Passed | G18: 46332
A19: admin_ord_11 | B19: Kiểm tra lọc đơn hàng theo Order status = 'Cancelled' | C19: Step: 1. Chọn Order status = [Cancelled] 2. Click nút [Search] | D19: 1. Bảng dữ liệu chỉ hiển thị các đơn hàng đã bị hủy (Cancelled). | E19: admin_ord_01 | F19: Passed | G19: 46333
A20: admin_ord_12 | B20: Kiểm tra lọc đơn hàng theo Payment status = 'Pending' | C20: Step: 1. Chọn Payment status = [Pending] 2. Click nút [Search] | D20: 1. Bảng dữ liệu chỉ hiển thị các đơn hàng chưa thực hiện thanh toán ('Pending'). | E20: admin_ord_01 | F20: Passed | G20: 46334
A21: admin_ord_13 | B21: Kiểm tra lọc đơn hàng theo Payment status = 'Authorized' | C21: Step: 1. Chọn Payment status = [Authorized] 2. Click nút [Search] | D21: 1. Bảng dữ liệu chỉ hiển thị các đơn hàng đã được tổ chức thanh toán xác thực giao dịch ('Authorized'). | E21: admin_ord_01 | F21: Passed | G21: 46335
A22: admin_ord_14 | B22: Kiểm tra lọc đơn hàng theo Payment status = 'Paid' | C22: Step: 1. Chọn Payment status = [Paid] 2. Click nút [Search] | D22: 1. Bảng dữ liệu chỉ hiển thị các đơn hàng đã thanh toán thành công ('Paid'). | E22: admin_ord_01 | F22: Passed | G22: 46336
A23: admin_ord_15 | B23: Kiểm tra lọc đơn hàng theo Payment status = 'Refunded' | C23: Step: 1. Chọn Payment status = [Refunded] 2. Click nút [Search] | D23: 1. Bảng dữ liệu chỉ hiển thị các đơn hàng đã hoàn tiền toàn phần ('Refunded'). | E23: admin_ord_01 | F23: Passed | G23: 46337
A24: admin_ord_16 | B24: Kiểm tra lọc đơn hàng theo Payment status = 'Voided' | C24: Step: 1. Chọn Payment status = [Voided] 2. Click nút [Search] | D24: 1. Bảng dữ liệu chỉ hiển thị các đơn hàng đã hủy bỏ giao dịch thanh toán ('Voided'). | E24: admin_ord_01 | F24: Passed | G24: 46338
A25: admin_ord_17 | B25: Kiểm tra lọc đơn hàng theo Payment status = 'Partially Refunded' | C25: Step: 1. Chọn Payment status = [Partially Refunded] 2. Click nút [Search] | D25: 1. Bảng dữ liệu chỉ hiển thị các đơn hàng được hoàn trả tiền một phần. | E25: admin_ord_01 | F25: Passed | G25: 46339
... A29: admin_ord_21 | B29: Kiểm tra tìm kiếm theo Email thanh toán với email đang tồn tại trong hệ thống | C29: Pre-condition: + Có đơn hàng của khách hàng 'steve_gates@nopCommerce.com'. Step: 1. Nhập 'steve_gates@nopCommerce.com' vào ô 'Billing email' 2. Click nút [Search] | D29: 1. Danh sách lọc và hiển thị chính xác các đơn hàng thuộc email 'steve_gates@nopCommerce.com'. | E29: admin_ord_01 | F29: Passed | G29: 46343
A30: admin_ord_22 | B30: Kiểm tra tìm kiếm theo Email thanh toán với định dạng sai cú pháp email | C30: Step: 1. Nhập 'email_sai_cu_phap@@test' vào ô 'Billing email' 2. Click nút [Search] | D30: 1. Hệ thống hiển thị cảnh báo sai cú pháp email. | E30: admin_ord_01 | F30: Failed | G30: 46344 | H30: Lỗi do thực tế không thông báo định dạng email bị sai
A31: admin_ord_23 | B31: Kiểm tra tìm kiếm theo Tên khách hàng (Billing Last Name) | C31: Step: 1. Nhập Last Name = 'Gates' vào ô tìm kiếm 2. Click nút [Search] | D31: 1. Danh sách hiển thị các đơn hàng có họ khách hàng chứa từ 'Gates'. | E31: admin_ord_01 | F31: Passed | G31: 46345
A32: admin_ord_24 | B32: Kiểm tra tìm kiếm theo từ khóa trong Ghi chú đơn hàng (Order notes) | C32: Step: 1. Nhập từ khóa 'khách VIP' vào ô 'Order notes' 2. Click nút [Search] | D32: 1. Bảng lọc và hiển thị các đơn hàng có nội dung ghi chú chứa từ 'khách VIP'. | E32: admin_ord_01 | F32: Passed | G32: 46346
A33: admin_ord_25 | B33: Kiểm tra chuyển sang trang kế tiếp | C33: Step: 1. Tại chân bảng đơn hàng, click nút [Next] hoặc số trang [2] | D33: 1. Bảng tải và hiển thị danh sách đơn hàng của trang 2. 2. Số thứ tự đơn hàng tiếp nối chính xác trang 1. | E33: admin_ord_01 | F33: Blocked | G33: 46347 | H33: Do đơn hàng không đủ nhiều để thực hiện chuyển trang
A34: admin_ord_26 | B34: Kiểm tra quay lại trang trước đó | C34: Pre-condition: + Đang đứng ở trang 2 của danh sách đơn hàng. Step: 1. Click nút [Previous] hoặc số trang [1] | D34: 1. Hệ thống quay trở lại và hiển thị danh sách đơn hàng của trang 1. | E34: admin_ord_25 | F34: Blocked | G34: 46348 | H34: Do chuyển trang kế tiếp không được nên không thể thực hiện được test case này
A35: admin_ord_27 | B35: Kiểm tra thay đổi số lượng bản ghi hiển thị trên trang (15, 20, 50, 100 dòng/trang) | C35: Step: 1. Chọn dropdown kích thước trang lần lượt là 20, 50, 100 dòng/trang | D35: 1. Số lượng dòng dữ liệu hiển thị trên bảng cập nhật tương ứng chính xác theo giá trị đã chọn. | E35: admin_ord_01 | F35: Passed | G35: 46349
A36: admin_ord_28 | B36: Kiểm tra điều hướng vào trang Chi tiết đơn hàng khi click nút [View] | C36: Step: 1. Click nút [View] tại dòng đơn hàng #1 | D36: 1. Hệ thống chuyển hướng vào màn hình xem chi tiết đơn hàng #1 (View order details - 1). | E36: admin_ord_01 | F36: Passed | G36: 46350
A37: admin_ord_29 | B37: Kiểm tra bố cục trang Chi tiết đơn hàng (tab Thông tin chung, Địa chỉ, Danh sách sản phẩm, Ghi chú) | C37: Step: 1. Quan sát giao diện trang Chi tiết đơn hàng | D37: 1. Hiển thị đầy đủ 4 tab chức năng: Info (Thông tin chung), Billing & Shipping (Địa chỉ), Products (Sản phẩm), Order notes (Ghi chú). | E37: admin_ord_28 | F37: Passed | G37: 46351
A38: admin_ord_30 | B38: Kiểm tra thay đổi tổng tiền đơn hàng với số âm | C38: Step: 1. Tại panel 'Order totals', click nút [Edit order total] 2. Nhập số tiền âm: Order total= '-50' 3. Click nút [Save] | D38: 1. Hệ thống báo lỗi validation không cho phép tổng tiền là số âm. 2. Giá trị tổng tiền cũ được giữ nguyên. | E38: admin_ord_28 | F38: Failed | G38: 46352 | H38: do thực tế không thông báo được nhập số tiền âm và nó lưu số tiền đó luôn
A39: admin_ord_31 | B39: Kiểm tra thay đổi tổng tiền của đơn hàng với số tiền cực lớn | C39: Step: 1. Tại panel 'Order totals', click nút [Edit order total] 2. Nhập số tiền cực lớn: '999999999999' 3. Click nút [Save] | D39: 1. Hệ thống cảnh báo giới hạn độ dài hoặc định dạng tiền tệ vượt quá ngưỡng cho phép. 2. Giá trị tổng tiền cũ được giữ nguyên. | E39: admin_ord_28 | F39: Failed | G39: 46353 | H39: do thực tế không thông báo được nhập số tiền cực lớn và nó lưu số tiền đó luôn
A40: admin_ord_32 | B40: Kiểm tra thay đổi tổng tiền của đơn hàng với số tiền thực tế | C40: Step: 1. Tại panel 'Order totals', click nút [Edit order total] 2. Nhập giá trị tổng tiền mới: '1500.00' 3. Click nút [Save] | D40: 1. Hiển thị thông báo lưu thành công. 2. Tổng tiền đơn hàng cập nhật thành $1,500.00 chính xác. | E40: admin_ord_28 | F40: Passed | G40: 46354
A41: admin_ord_33 | B41: Kiểm tra cập nhật trạng thái đơn hàng từ 'Pending' sang 'Processing' | C41: Step: 1. Tại trang chi tiết đơn hàng đang ở 'Pending' 2. Click nút [Change status] 3. Chọn trạng thái mới = 'Processing' 4. Click nút [Save] | D41: 1. HIển thị list trạng thái có thể thay đổi gồm "Processing" 2. Thông tin trạng thái đơn hiển thị 'Processing'. | E41: admin_ord_28 | F41: Passed | G41: 46355
A42: admin_ord_34 | B42: Kiểm tra cập nhật trạng thái đơn hàng từ 'Processing' sang 'Complete' | C42: Step: 1. Tại chi tiết đơn hàng đang ở 'Processing' 2. Click nút [Change status] 3. Chọn 'Complete' 4. Click [Save] | D42: 1. HIển thị list trạng thái có thể thay đổi gồm "Complete" 2. Thông tin trạng thái đơn hiển thị 'Complete'. | E42: admin_ord_33 | F42: Passed | G42: 46356
A43: admin_ord_35 | B43: Kiểm tra hủy đơn hàng và chuyển trạng thái sang 'Cancelled' | C43: Step: 1. Click nút [Cancel order] trên thanh công cụ chi tiết đơn hàng 2. Xác nhận popup cảnh báo hủy đơn | D43: 1. Đơn hàng chuyển sang trạng thái 'Cancelled'. 2. Các nút thao tác thanh toán và xuất kho bị khóa lại. | E43: admin_ord_28 | F43: Passed | G43: 46357
A44: admin_ord_36 | B44: Kiểm tra thêm ghi chú đơn hàng có chọn 'Display to customer' | C44: Step: 1. Tại tab Order notes, nhập nội dung ghi chú: 'Đơn hàng đang chuẩn bị xuất kho' 2. Đánh dấu chọn 'Display to customer' 3. Click nút [Add order note] | D44: 1. Ghi chú được thêm vào danh sách lịch sử. 2. Cột 'Display to customer' hiển thị dấu tích xanh và hiển thị được ngoài Storefront. | E44: admin_ord_28 | F44: Passed | G44: 46358
A45: admin_ord_37 | B45: Kiểm tra thêm ghi chú đơn hàng không chọn 'Display to customer' | C45: Step: 1. Nhập ghi chú nội bộ: 'Kiểm tra kỹ thông tin thanh toán trước khi ship' 2. Bỏ chọn 'Display to customer' 3. Click nút [Add order note] | D45: 1. Ghi chú được lưu nội bộ thành công. 2. Cột 'Display to customer' hiển thị dấu chéo đỏ (khách không xem được ngoài Storefront). | E45: admin_ord_28 | F45: Passed | G45: 46359
...

Sheet Admin - Shipments
A2: Module Code | B2: Admin_Shipments
A3: Test requirement | B3: Quản lý Giao hàng (Admin - Shipments)
A4: Tester | B4: Trương Cao Đoàn
A5: Passed | B5: Failed | C5: Untested | D5: Blocked | E5: Skipped | F5: Number of Test cases
A6: =COUNTIF(F9:F28, "Passed") -> 18 | B6: =COUNTIF(F9:F28, "Failed") -> 2 | C6: =COUNTBLANK(F9:F28) + COUNTIF(F9:F28, "Untested") -> 0 | D6: =COUNTIF(F9:F28, "Blocked") -> 0 | E6: =COUNTIF(F9:F28, "Skipped") -> 0 | F6: =COUNTA(A9:A28) -> 20
A8: ID | B8: Test Case Description | C8: Test Case Procedure | D8: Expected Output | E8: Inter-test case Dependence | F8: Result | G8: Test date | H8: Note
A9: admin_ship_01 | B9: Kiểm tra hiển thị danh sách các chuyến giao hàng khi click [admin > Shipments] | C9: Pre-condition: + Đăng nhập tài khoản Quản trị viên (Admin). Step: 1. Tại menu [admin] 2. Click chọn [Shipments] | D9: 1. Màn hình Shipments được hiển thị. | E9: None | F9: Passed | G9: 46323
A10: admin_ship_02 | B10: Kiểm tra trạng thái hiển thị mặc định của bảng giao hàng | C10: Step: 1. Truy cập màn hình Shipments 2. Quan sát bảng dữ liệu ban đầu | D10: 1. Bảng hiển thị danh sách các chuyến giao hàng hiện có trong hệ thống. 2. Các ô lọc tìm kiếm ban đầu ở trạng thái trống. | E10: admin_ship_01 | F10: Passed | G10: 46323
A11: admin_ship_03 | B11: Kiểm tra lọc danh sách giao hàng theo Mã vận đơn (Tracking number) không tồn tại | C11: Step: 1. Nhập Tracking number = 'MA_KHONG_TON_TAI_999' 2. Click nút [Search] | D11: 1. Bảng dữ liệu không hiển thị bản ghi nào. 2. Hiển thị thông báo 'No data available in table'. | E11: admin_ship_01 | F11: Passed | G11: 46323
A12: admin_ship_04 | B12: Kiểm tra lọc danh sách giao hàng theo Mã vận đơn (Tracking number) tồn tại | C12: Pre-condition: + Có chuyến hàng với Tracking number = 'VNPOST_123456'. Step: 1. Nhập Tracking number = 'VNPOST_123456' 2. Click nút [Search] | D12: 1. Danh sách lọc và hiển thị chính xác chuyến hàng có mã vận đơn 'VNPOST_123456'. | E12: admin_ship_01 | F12: Passed | G12: 46323
A13: admin_ship_05 | B13: Kiểm tra lọc danh sách giao hàng theo Quốc gia | C13: Step: 1. Chọn Country = [United States of America] 2. Click nút [Search] | D13: 1. Hiển thị danh sách các option quốc gia trong đó có United States 2.. Bảng dữ liệu hiển thị các chuyến hàng có địa chỉ người nhận thuộc quốc gia United States. | E13: admin_ship_01 | F13: Passed | G13: 46323
A14: admin_ship_06 | B14: Kiểm tra lọc danh sách giao hàng theo khoảng ngày xuất kho hợp lệ (start date <= end date) | C14: Step: 1. Chọn Start date = '2026-10-01' 2. Chọn End date = '2026-10-20' 3. Click nút [Search] | D14: 1. Danh sách hiển thị các chuyến hàng có Shipped date nằm trong khoảng từ 2026-10-01 đến 2026-10-20. | E14: admin_ship_01 | F14: Passed | G14: 46323
A15: admin_ship_07 | B15: Kiểm tra lọc danh sách giao hàng theo khoảng ngày xuất kho không hợp lệ (start date > end date) | C15: Step: 1. Chọn Start date = '2026-10-20' 2. Chọn End date = '2026-10-01' 3. Click nút [Search] | D15: 1. Hệ thống thông báo ngày không hợp lệ 2. Hiển thị thông báo 'No data available in table'. | E15: admin_ship_01 | F15: Failed | G15: 46323 | H15: Thực tế hệ thống tiến hành tìm kiếm chứ không thông báo ngày nhận không hợp lệ
A16: admin_ship_08 | B16: Kiểm tra lọc danh sách giao hàng khi chỉ nhập Start date | C16: Step: 1. Nhập Start date = '2026-10-01' 2. Để trống End date 3. Click nút [Search] | D16: 1. Hiển thị tất cả các chuyến hàng được xuất kho từ ngày 2026-10-01 trở về sau. | E16: admin_ship_01 | F16: Passed | G16: 46323
A17: admin_ship_09 | B17: Kiểm tra lọc danh sách giao hàng khi chỉ nhập End date | C17: Step: 1. Để trống Start date 2. Nhập End date = '2026-10-20' 3. Click nút [Search] | D17: 1. Hiển thị tất cả các chuyến hàng xuất kho trước hoặc trong ngày 2026-10-20. | E17: admin_ship_01 | F17: Passed | G17: 46323
A18: admin_ship_10 | B18: Kiểm tra phân trang danh sách chuyến giao hàng | C18: Step: 1. Tại chân bảng Shipments, click nút [Next] hoặc số trang [2] 2. Click nút [Previous] hoặc số trang [1] | D18: 1. Chuyển sang trang 2 và quay lại trang 1 mượt mà, dữ liệu không bị trùng lặp. | E18: admin_ship_01 | F18: Passed | G18: 46323
A19: admin_ship_11 | B19: Kiểm tra xem màn hình chi tiết chuyến giao hàng | C19: Step: 1. Click nút [View] tại chuyến giao hàng #1 | D19: 1. Điều hướng vào trang chi tiết chuyến hàng (View shipment details). | E19: admin_ship_01 | F19: Passed | G19: 46323
A20: admin_ship_12 | B20: Kiểm tra cập nhật trạng thái 'Set as shipped' có nhập mã vận đơn Tracking number hợp lệ | C20: Step: 1. Tại chi tiết chuyến hàng chưa xuất kho, nhập Tracking number = 'VNPOST_654321' 2. Click nút [Set as shipped] | D20: 2. Cột Shipped date được tự động ghi nhận ngày giờ hiện tại. | E20: admin_ship_11 | F20: Passed | G20: 46323
A21: admin_ship_13 | B21: Kiểm tra cập nhật trạng thái 'Set as shipped' khi không nhập mã vận đơn | C21: Step: 1. Để trống ô Tracking number 2. Click nút [Set as shipped] | D21: 1. Hệ thống cho phép chuyển trạng thái Shipped hoặc cảnh báo tùy cấu hình cửa hàng. | E21: admin_ship_11 | F21: Passed | G21: 46323
A22: admin_ship_14 | B22: Kiểm tra cập nhật trạng thái 'Set as delivered' hoàn tất giao hàng | C22: Step: 1. Tại chuyến hàng đã ở trạng thái Shipped 2. Click nút [Set as delivered] | D22: 1. Trạng thái chuyến hàng chuyển thành Delivered. 2. Cột Delivery date được ghi nhận ngày giờ giao hàng thành công. | E22: admin_ship_12 | F22: Passed | G22: 46323
A23: admin_ship_15 | B23: Kiểm tra cập nhật Date ready for pickup và Date delivered hợp lệ (Date ready for pickup <= Date delivered) | C23: Step: 1. Nhập Date ready for pickup = '2026-10-20' 2. Nhập Date delivered = '2026-10-22' 3. Click nút [Save] | D23: 1. Hiển thị thông báo 'Shipment has been updated successfully' và dữ liệu hiển Date ready for pickup = '2026-10-20' và Date delivered = '2026-10-22' . | E23: admin_ship_11 | F23: Passed | G23: 46323
A24: admin_ship_16 | B24: Kiểm tra cập nhật Date ready for pickup và Date delivered không hợp lệ (Date ready for pickup > Date delivered) | C24: Step: 1. Tại chuyến hàng, nhập Date ready for pickup = '2026-10-22' 2. Nhập Date delivered = '2026-10-20' 3. Click nút [Save] | D24: 1. Hệ thống hiển thị cảnh báo lỗi logic: Ngày sẵn sàng lấy hàng không thể lớn hơn ngày giao hàng. 2. Dữ liệu hiển thị không được cập nhật Date ready for pickup và Date delivered. | E24: admin_ship_11 | F24: Failed | G24: 46323 | H24: Thực tế hệ thống tiến hành tìm kiếm chứ không thông báo ngày nhận không hợp lệ
A25: admin_ship_17 | B25: Kiểm tra cập nhật thêm ghi chú nội bộ cho chuyến giao hàng | C25: Step: 1. Nhập ghi chú vào ô 'Admin comment': 'Khách hẹn giao sau 18h' 2. Click nút [Save] | D25: 1. Ghi chú được lưu lại trong chi tiết chuyến hàng. | E25: admin_ship_11 | F25: Passed | G25: 46323
A26: admin_ship_18 | B26: Kiểm tra in phiếu đóng gói giao hàng PDF (Print packaging slip) | C26: Step: 1. Tại trang chi tiết chuyến hàng, click nút [Print packaging slip all] | D26: 1. Tệp PDF phiếu đóng gói được tải xuống hiển thị đầy đủ thông tin địa chỉ giao, danh sách hàng và số lượng. | E26: admin_ship_11 | F26: Passed | G26: 46323
A27: admin_ship_19 | B27: Kiểm tra in phiếu đóng gói PDF cho các chuyến hàng được chọn trong danh sách | C27: Step: 1. Tại bảng danh sách Shipments, tick chọn 2 chuyến hàng 2. Click nút [Print packaging slips (selected)] | D27: 1. Tệp PDF tổng hợp các phiếu đóng gói của 2 chuyến hàng đã chọn được tải xuống thành công. | E27: admin_ship_01 | F27: Passed | G27: 46323
A28: admin_ship_20 | B28: Kiểm tra xóa một chuyến giao hàng | C28: Step: 1. Tại chi tiết chuyến hàng, click nút [Delete] 2. Xác nhận hộp thoại cảnh báo xóa | D28: 1. Hiển thị popup xác nhận. 2. Chuyến hàng bị xóa khỏi hệ thống. Quay lại danh sách với thông báo 'The shipment has been deleted successfully'. | E28: admin_ship_11 | F28: Passed | G28: 46323

Sheet Admin - Gift cards
A2: Module Code | B2: Admin_GiftCards | G2: Trương Cao Đoàn
A3: Test requirement | B3: Quản lý Thẻ quà tặng (Admin - Gift cards)
A4: Tester | B4: Trương Cao Đoàn
A5: Passed | B5: Failed | C5: Untested | D5: Blocked | E5: Skipped | F5: Number of Test cases
A6: =COUNTIF(F9:F28, "Passed") -> 16 | B6: =COUNTIF(F9:F28, "Failed") -> 4 | C6: =COUNTBLANK(F9:F28) + COUNTIF(F9:F28, "Untested") -> 0 | D6: =COUNTIF(F9:F28, "Blocked") -> 0 | E6: =COUNTIF(F9:F28, "Skipped") -> 0 | F6: =COUNTA(A9:A28) -> 20
A8: ID | B8: Test Case Description | C8: Test Case Procedure | D8: Expected Output | E8: Inter-test case Dependence | F8: Result | G8: Test date | H8: Note
A9: admin_gc_01 | B9: Kiểm tra hiển thị màn hình danh sách bố cục thẻ quà tặng khi click [admin > Gift cards] | C9: Pre-condition: + Đăng nhập tài khoản Quản trị viên (Admin). Step: 1. Tại menu [admin], click chọn [Gift cards] | D9: 1. Hiển thị màn hình Gift cards. | E9: None | F9: Passed | G9: 46324
A10: admin_gc_02 | B10: Kiểm tra tìm kiếm thẻ quà tặng theo Coupon code đang tồn tại | C10: Pre-condition: + Có thẻ quà tặng với mã 'TEST_GC_100'. Step: 1. Nhập 'TEST_GC_100' vào ô 'Coupon code' 2. Click nút [Search] | D10: 1. Bảng dữ liệu lọc và hiển thị chính xác thẻ quà tặng có mã 'TEST_GC_100'. | E10: admin_gc_01 | F10: Passed | G10: 46324
A11: admin_gc_03 | B11: Kiểm tra tìm kiếm thẻ quà tặng theo Coupon code không tồn tại | C11: Step: 1. Nhập 'MA_KHONG_TON_TAI_999' vào ô Coupon code 2. Click nút [Search] | D11: 1. Thông báo 'No data available in table'. | E11: admin_gc_01 | F11: Passed | G11: 46324
A12: admin_gc_04 | B12: Kiểm tra lọc thẻ quà tặng theo trạng thái kích hoạt = 'Activated' | C12: Step: 1. Chọn Activated = [Activated] 2. Click nút [Search] | D12: 1. Danh sách chỉ hiển thị các thẻ quà tặng đang được kích hoạt (cột Is activated có dấu tích xanh). | E12: admin_gc_01 | F12: Passed | G12: 46324
A13: admin_gc_05 | B13: Kiểm tra lọc thẻ quà tặng theo trạng thái kích hoạt = 'Deactivated' | C13: Step: 1. Chọn Activated = [Deactivated] 2. Click nút [Search] | D13: 1. Danh sách chỉ hiển thị các thẻ quà tặng đã bị vô hiệu hóa (cột Is activated có dấu chéo đỏ). | E13: admin_gc_01 | F13: Passed | G13: 46324
A14: admin_gc_06 | B14: Kiểm tra tìm kiếm thẻ quà tặng theo Tên người nhận (Recipient name) | C14: Step: 1. Nhập Tên người nhận = 'Nguyễn Văn B' 2. Click nút [Search] | D14: 1. Bảng lọc ra đúng các thẻ quà tặng gửi cho người nhận 'Nguyễn Văn B'. | E14: admin_gc_01 | F14: Passed | G14: 46324
A15: admin_gc_07 | B15: Kiểm tra chức năng sinh mã thẻ ngẫu nhiên tự động [Generate code] | C15: Step: 1. Click nút [Add new] để tạo thẻ quà tặng 2. Click nút [Generate code] tại trường Coupon code | D15: 1. Hiển thị form nhập thông tin thẻ quà tặng 2. Tự động hiển tự mã code trong trường Coupon code | E15: admin_gc_01 | F15: Passed | G15: 46324
A16: admin_gc_08 | B16: Kiểm tra lưu thẻ quà tặng mới với đầy đủ các trường bắt buộc (Giá trị ban đầu, Tên/Email người nhận) | C16: Step: 1. Nhập Initial value = '100' 2. Nhập Coupon code = 'TEST_GC_100' 3. Nhập Recipient name = 'Nguyễn Văn B' 4. Nhập Recipient email = 'vanb@gmail.com' 5. Click nút [Save] | D16: 1. Thẻ quà tặng được lưu thành công vào hệ thống và hiển thị thông báo: 'The new gift card has been added successfully.' | E16: admin_gc_07 | F16: Passed | G16: 46324
A17: admin_gc_09 | B17: Kiểm tra nhập Initial value với số tiền hợp lệ | C17: Step: 1. Tại form tạo thẻ quà tặng, nhập Initial value = '500' 2. Điền các trường bắt buộc khác và click nút [Save] | D17: 1. Thẻ quà tặng được tạo thành công với mệnh giá ban đầu là $500.00. | E17: admin_gc_07 | F17: Passed | G17: 46324
A18: admin_gc_10 | B18: Kiểm tra nhập Initial value với số tiền không hợp lệ (số âm) | C18: Step: 1. Tại form tạo thẻ quà tặng, nhập Initial value = '-50' 2. Click nút [Save] | D18: 1. Hệ thống hiển thị thông báo lỗi yêu cầu giá trị thẻ quà tặng phải lớn hơn 0. 2. Không tạo thẻ quà tặng. | E18: admin_gc_07 | F18: Failed | G18: 46324 | H18: Thực tế hệ thống không thông báo "giá trị thẻ quà tặng phải lớn hơn 0" Hệ thống lưu thẻ quà tặng
A19: admin_gc_11 | B19: Kiểm tra nhập Initial value bằng 0 (Kỹ thuật BVA) | C19: Step: 1. Nhập Initial value = '0' 2. Điền các trường khác và click [Save] | D19: 1. Hệ thống báo lỗi giá trị ban đầu phải lớn hơn 0. 2. Thẻ quà tặng không được tạo. | E19: admin_gc_07 | F19: Failed | G19: 46324 | H19: Thực tế hệ thống không thông báo "giá trị thẻ quà tặng phải lớn hơn 0" Hệ thống lưu thẻ quà tặng
A20: admin_gc_12 | B20: Kiểm tra để trống trường bắt buộc Tên người nhận (Recipient name) | C20: Step: 1. Nhập Initial value = '100' 2. Để trống ô 'Recipient name' 3. Nhập email người nhận hợp lệ 4. Click [Save] | D20: 1. Hệ thống cảnh báo lỗi bắt buộc nhập tên người nhận. 2. Dữ liệu gift card không được lưu. | E20: admin_gc_07 | F20: Failed | G20: 46324 | H20: Thực tế hệ thống không thông báo "buộc nhập tên người nhận" Hệ thống lưu thẻ quà tặng
A21: admin_gc_13 | B21: Kiểm tra để trống trường bắt buộc Email người nhận (Recipient email) với thẻ loại Virtual | C21: Step: 1. Chọn Gift card type = Virtual 2. Để trống ô 'Recipient email' 3. Điền các trường khác và click [Save] | D21: 1. Hệ thống cảnh báo lỗi bắt buộc nhập email người nhận đối với thẻ ảo. 2. Không lưu form. | E21: admin_gc_07 | F21: Failed | G21: 46324 | H21: Thực tế hệ thống không thông báo "bắt buộc nhập email người nhận đối với thẻ ảo" Hệ thống lưu thẻ quà tặng
A22: admin_gc_14 | B22: Kiểm tra nhập Email người nhận sai định dạng cú pháp | C22: Step: 1. Nhập Recipient email = 'email_khong_hop_le@@abc' 2. Click [Save] | D22: 1. Hệ thống báo lỗi validation 'Wrong email'. 2. Thẻ không được lưu. | E22: admin_gc_07 | F22: Passed | G22: 46324
A23: admin_gc_15 | B23: Kiểm tra tạo thẻ quà tặng loại vật lý (Physical gift card) | C23: Step: 1. Chọn Gift card type = [Physical] 2. Nhập Initial value, Coupon code, Recipient name 3. Click [Save] | D23: 1. Thẻ quà tặng loại vật lý được tạo thành công mà không bắt buộc nhập email người nhận. | E23: admin_gc_07 | F23: Passed | G23: 46324
A24: admin_gc_16 | B24: Kiểm tra kích hoạt thẻ quà tặng (Is activated = True) | C24: Step: 1. Tại màn hình sửa thẻ quà tặng, đánh dấu chọn checkbox 'Is gift card activated' 2. Click nút [Save] | D24: 1. Thẻ quà tặng chuyển sang trạng thái đã kích hoạt (biểu tượng tích xanh). 2. Mã thẻ có thể sử dụng để thanh toán ngoài Storefront. | E24: admin_gc_08 | F24: Passed | G24: 46324
A25: admin_gc_17 | B25: Kiểm tra vô hiệu hóa thẻ quà tặng (Is activated = False) | C25: Step: 1. Bỏ chọn checkbox 'Is gift card activated' 2. Click nút [Save] | D25: 1. Thẻ quà tặng chuyển sang trạng thái vô hiệu hóa (biểu tượng dấu chéo đỏ). 2. Mã thẻ không còn áp dụng được khi đặt hàng. | E25: admin_gc_08 | F25: Passed | G25: 46324
A26: admin_gc_18 | B26: Kiểm tra gửi email thông báo mã thẻ quà tặng cho người nhận [Notify recipient] | C26: Step: 1. Tại màn hình sửa thẻ quà tặng đã kích hoạt 2. Click nút [Notify recipient] 3. Xác nhận popup gửi email | D26: 1. Hệ thống gửi email chứa mã coupon tới email người nhận thành công. 2. Hiển thị thông báo 'Notification email has been sent'. | E26: admin_gc_16 | F26: Passed | G26: 46324
A27: admin_gc_19 | B27: Kiểm tra xem lịch sử sử dụng của thẻ quà tặng (Usage history) | C27: Step: 1. Tại chi tiết thẻ quà tặng, cuộn xuống bảng 'Usage history' | D27: 1. Bảng hiển thị các đơn hàng đã sử dụng thẻ quà tặng này kèm số tiền đã trừ và ngày sử dụng. | E27: admin_gc_08 | F27: Passed | G27: 46324
A28: admin_gc_20 | B28: Kiểm tra xóa thẻ quà tặng | C28: Step: 1. Tại chi tiết thẻ quà tặng, click nút [Delete] 2. Xác nhận hộp thoại cảnh báo xóa | D28: 1. Thẻ quà tặng bị xóa hoàn toàn khỏi hệ thống. 2. Quay lại danh sách với thông báo xóa thành công. | E28: admin_gc_08 | F28: Passed | G28: 46324

Sheet Test Report
B2: TEST REPORT
B4: Project Name | C4: nopCommerce Admin Sales Management | F4: Creator | G4: Trương Cao Đoàn
B5: Project Code | C5: NOP-SALES-2026 | F5: Reviewer/Approver | G5: ThS. Trần Thị Thanh Nga
B6: Document Code | C6: NOP-SALES_TestReport_v1.0 | F6: Issue Date | G6: 2026-10-21
B7: Notes | C7: Báo cáo kiểm thử phân hệ Quản lý bán hàng: Orders (44 TCs), Shipments (20 TCs), Gift cards (20 TCs) | F7: Version | G7: 1.0
B10: No | C10: Module code | D10: Pass | E10: Fail | F10: Untested | G10: Blocked | H10: Skipped | I10: Number of test cases
B11: 1 | C11: Admin_Orders | D11: ='Admin - Orders'!A6 -> 37 | E11: ='Admin - Orders'!B6 -> 5 | F11: ='Admin - Orders'!C6 -> 0 | G11: ='Admin - Orders'!D6 -> 2 | H11: ='Admin - Orders'!E6 -> 0 | I11: ='Admin - Orders'!F6 -> 44
B12: 2 | C12: Admin_Shipments | D12: ='Admin - Shipments'!A6 -> 18 | E12: ='Admin - Shipments'!B6 -> 2 | F12: ='Admin - Shipments'!C6 -> 0 | G12: ='Admin - Shipments'!D6 -> 0 | H12: ='Admin - Shipments'!E6 -> 0 | I12: ='Admin - Shipments'!F6 -> 20
B13: 3 | C13: Admin_GiftCards | D13: ='Admin - Gift cards'!A6 -> 16 | E13: ='Admin - Gift cards'!B6 -> 4 | F13: ='Admin - Gift cards'!C6 -> 0 | G13: ='Admin - Gift cards'!D6 -> 0 | H13: ='Admin - Gift cards'!E6 -> 0 | I13: ='Admin - Gift cards'!F6 -> 20
C14: Sub total | D14: =SUM(D11:D13) -> 71 | E14: =SUM(E11:E13) -> 11 | F14: =SUM(F11:F13) -> 0 | G14: =SUM(G11:G13) -> 2 | H14: =SUM(H11:H13) -> 0 | I14: =SUM(I11:I13) -> 84
C16: Test coverage | E16: =IF(I14-H14=0, 0, (D14+E14)/(I14-H14)*100) -> 97.619048 | F16: %
C17: Test successful coverage | E17: =IF(D14+E14=0, 0, D14/(D14+E14)*100) -> 86.585366 | F17: %
